ERROR 2025-02-13 17:04:03,660 log Internal Server Error: /users/api/login/
Traceback (most recent call last):
  File "C:\Users\User\Desktop\docs\.venv\Lib\site-packages\asgiref\sync.py", line 518, in thread_handler
    raise exc_info[1]
  File "C:\Users\User\Desktop\docs\.venv\Lib\site-packages\django\core\handlers\exception.py", line 42, in inner
    response = await get_response(request)
               ^^^^^^^^^^^^^^^^^^^^^^^^^^^
  File "C:\Users\User\Desktop\docs\.venv\Lib\site-packages\asgiref\sync.py", line 518, in thread_handler
    raise exc_info[1]
  File "C:\Users\User\Desktop\docs\.venv\Lib\site-packages\django\core\handlers\base.py", line 253, in _get_response_async
    response = await wrapped_callback(
               ^^^^^^^^^^^^^^^^^^^^^^^
        request, *callback_args, **callback_kwargs
        ^^^^^^^^^^^^^^^^^^^^^^^^^^^^^^^^^^^^^^^^^^
    )
    ^
  File "C:\Users\User\Desktop\docs\.venv\Lib\site-packages\asgiref\sync.py", line 468, in __call__
    ret = await asyncio.shield(exec_coro)
          ^^^^^^^^^^^^^^^^^^^^^^^^^^^^^^^
  File "C:\Users\User\AppData\Local\Programs\Python\Python313\Lib\concurrent\futures\thread.py", line 59, in run
    result = self.fn(*self.args, **self.kwargs)
  File "C:\Users\User\Desktop\docs\.venv\Lib\site-packages\asgiref\sync.py", line 522, in thread_handler
    return func(*args, **kwargs)
  File "C:\Users\User\Desktop\docs\.venv\Lib\site-packages\django\views\decorators\csrf.py", line 65, in _view_wrapper
    return view_func(request, *args, **kwargs)
  File "C:\Users\User\Desktop\docs\.venv\Lib\site-packages\django\views\generic\base.py", line 104, in view
    return self.dispatch(request, *args, **kwargs)
           ~~~~~~~~~~~~~^^^^^^^^^^^^^^^^^^^^^^^^^^
  File "C:\Users\User\Desktop\docs\.venv\Lib\site-packages\rest_framework\views.py", line 509, in dispatch
    response = self.handle_exception(exc)
  File "C:\Users\User\Desktop\docs\.venv\Lib\site-packages\rest_framework\views.py", line 469, in handle_exception
    self.raise_uncaught_exception(exc)
    ~~~~~~~~~~~~~~~~~~~~~~~~~~~~~^^^^^
  File "C:\Users\User\Desktop\docs\.venv\Lib\site-packages\rest_framework\views.py", line 480, in raise_uncaught_exception
    raise exc
  File "C:\Users\User\Desktop\docs\.venv\Lib\site-packages\rest_framework\views.py", line 506, in dispatch
    response = handler(request, *args, **kwargs)
  File "C:\Users\User\Desktop\docs\taskmanager\users\views.py", line 58, in post
    logger.warning(f'Неудачный вход {user.email} неверные данные')
                                     ^^^^^^^^^^
AttributeError: 'NoneType' object has no attribute 'email'
ERROR 2025-02-13 17:04:03,668 runserver HTTP POST /users/api/login/ 500 [0.77, 127.0.0.1:55174]
WARNING 2025-02-13 17:04:53,564 log Unauthorized: /users/api/logout/
WARNING 2025-02-13 17:04:53,565 runserver HTTP POST /users/api/logout/ 401 [0.01, 127.0.0.1:55174]
ERROR 2025-02-13 17:05:02,287 log Internal Server Error: /users/api/login/
Traceback (most recent call last):
  File "C:\Users\User\Desktop\docs\.venv\Lib\site-packages\asgiref\sync.py", line 518, in thread_handler
    raise exc_info[1]
  File "C:\Users\User\Desktop\docs\.venv\Lib\site-packages\django\core\handlers\exception.py", line 42, in inner
    response = await get_response(request)
               ^^^^^^^^^^^^^^^^^^^^^^^^^^^
  File "C:\Users\User\Desktop\docs\.venv\Lib\site-packages\asgiref\sync.py", line 518, in thread_handler
    raise exc_info[1]
  File "C:\Users\User\Desktop\docs\.venv\Lib\site-packages\django\core\handlers\base.py", line 253, in _get_response_async
    response = await wrapped_callback(
               ^^^^^^^^^^^^^^^^^^^^^^^
        request, *callback_args, **callback_kwargs
        ^^^^^^^^^^^^^^^^^^^^^^^^^^^^^^^^^^^^^^^^^^
    )
    ^
  File "C:\Users\User\Desktop\docs\.venv\Lib\site-packages\asgiref\sync.py", line 468, in __call__
    ret = await asyncio.shield(exec_coro)
          ^^^^^^^^^^^^^^^^^^^^^^^^^^^^^^^
  File "C:\Users\User\AppData\Local\Programs\Python\Python313\Lib\concurrent\futures\thread.py", line 59, in run
    result = self.fn(*self.args, **self.kwargs)
  File "C:\Users\User\Desktop\docs\.venv\Lib\site-packages\asgiref\sync.py", line 522, in thread_handler
    return func(*args, **kwargs)
  File "C:\Users\User\Desktop\docs\.venv\Lib\site-packages\django\views\decorators\csrf.py", line 65, in _view_wrapper
    return view_func(request, *args, **kwargs)
  File "C:\Users\User\Desktop\docs\.venv\Lib\site-packages\django\views\generic\base.py", line 104, in view
    return self.dispatch(request, *args, **kwargs)
           ~~~~~~~~~~~~~^^^^^^^^^^^^^^^^^^^^^^^^^^
  File "C:\Users\User\Desktop\docs\.venv\Lib\site-packages\rest_framework\views.py", line 509, in dispatch
    response = self.handle_exception(exc)
  File "C:\Users\User\Desktop\docs\.venv\Lib\site-packages\rest_framework\views.py", line 469, in handle_exception
    self.raise_uncaught_exception(exc)
    ~~~~~~~~~~~~~~~~~~~~~~~~~~~~~^^^^^
  File "C:\Users\User\Desktop\docs\.venv\Lib\site-packages\rest_framework\views.py", line 480, in raise_uncaught_exception
    raise exc
  File "C:\Users\User\Desktop\docs\.venv\Lib\site-packages\rest_framework\views.py", line 506, in dispatch
    response = handler(request, *args, **kwargs)
  File "C:\Users\User\Desktop\docs\taskmanager\users\views.py", line 58, in post
    logger.warning(f'Неудачный вход {user.email} неверные данные')
                                     ^^^^^^^^^^
AttributeError: 'NoneType' object has no attribute 'email'
ERROR 2025-02-13 17:05:02,290 runserver HTTP POST /users/api/login/ 500 [0.73, 127.0.0.1:55174]
ERROR 2025-02-13 17:08:42,004 log Internal Server Error: /users/api/login/
Traceback (most recent call last):
  File "C:\Users\User\Desktop\docs\.venv\Lib\site-packages\asgiref\sync.py", line 518, in thread_handler
    raise exc_info[1]
  File "C:\Users\User\Desktop\docs\.venv\Lib\site-packages\django\core\handlers\exception.py", line 42, in inner
    response = await get_response(request)
               ^^^^^^^^^^^^^^^^^^^^^^^^^^^
  File "C:\Users\User\Desktop\docs\.venv\Lib\site-packages\asgiref\sync.py", line 518, in thread_handler
    raise exc_info[1]
  File "C:\Users\User\Desktop\docs\.venv\Lib\site-packages\django\core\handlers\base.py", line 253, in _get_response_async
    response = await wrapped_callback(
               ^^^^^^^^^^^^^^^^^^^^^^^
        request, *callback_args, **callback_kwargs
        ^^^^^^^^^^^^^^^^^^^^^^^^^^^^^^^^^^^^^^^^^^
    )
    ^
  File "C:\Users\User\Desktop\docs\.venv\Lib\site-packages\asgiref\sync.py", line 468, in __call__
    ret = await asyncio.shield(exec_coro)
          ^^^^^^^^^^^^^^^^^^^^^^^^^^^^^^^
  File "C:\Users\User\AppData\Local\Programs\Python\Python313\Lib\concurrent\futures\thread.py", line 59, in run
    result = self.fn(*self.args, **self.kwargs)
  File "C:\Users\User\Desktop\docs\.venv\Lib\site-packages\asgiref\sync.py", line 522, in thread_handler
    return func(*args, **kwargs)
  File "C:\Users\User\Desktop\docs\.venv\Lib\site-packages\django\views\decorators\csrf.py", line 65, in _view_wrapper
    return view_func(request, *args, **kwargs)
  File "C:\Users\User\Desktop\docs\.venv\Lib\site-packages\django\views\generic\base.py", line 104, in view
    return self.dispatch(request, *args, **kwargs)
           ~~~~~~~~~~~~~^^^^^^^^^^^^^^^^^^^^^^^^^^
  File "C:\Users\User\Desktop\docs\.venv\Lib\site-packages\rest_framework\views.py", line 509, in dispatch
    response = self.handle_exception(exc)
  File "C:\Users\User\Desktop\docs\.venv\Lib\site-packages\rest_framework\views.py", line 469, in handle_exception
    self.raise_uncaught_exception(exc)
    ~~~~~~~~~~~~~~~~~~~~~~~~~~~~~^^^^^
  File "C:\Users\User\Desktop\docs\.venv\Lib\site-packages\rest_framework\views.py", line 480, in raise_uncaught_exception
    raise exc
  File "C:\Users\User\Desktop\docs\.venv\Lib\site-packages\rest_framework\views.py", line 506, in dispatch
    response = handler(request, *args, **kwargs)
  File "C:\Users\User\Desktop\docs\taskmanager\users\views.py", line 58, in post
    logger.warning(f'Неудачный вход {user.email} неверные данные')
                                     ^^^^^^^^^^
AttributeError: 'NoneType' object has no attribute 'email'
ERROR 2025-02-13 17:08:42,008 runserver HTTP POST /users/api/login/ 500 [0.83, 127.0.0.1:55197]
ERROR 2025-02-13 17:08:48,522 log Internal Server Error: /users/api/login/
Traceback (most recent call last):
  File "C:\Users\User\Desktop\docs\.venv\Lib\site-packages\asgiref\sync.py", line 518, in thread_handler
    raise exc_info[1]
  File "C:\Users\User\Desktop\docs\.venv\Lib\site-packages\django\core\handlers\exception.py", line 42, in inner
    response = await get_response(request)
               ^^^^^^^^^^^^^^^^^^^^^^^^^^^
  File "C:\Users\User\Desktop\docs\.venv\Lib\site-packages\asgiref\sync.py", line 518, in thread_handler
    raise exc_info[1]
  File "C:\Users\User\Desktop\docs\.venv\Lib\site-packages\django\core\handlers\base.py", line 253, in _get_response_async
    response = await wrapped_callback(
               ^^^^^^^^^^^^^^^^^^^^^^^
        request, *callback_args, **callback_kwargs
        ^^^^^^^^^^^^^^^^^^^^^^^^^^^^^^^^^^^^^^^^^^
    )
    ^
  File "C:\Users\User\Desktop\docs\.venv\Lib\site-packages\asgiref\sync.py", line 468, in __call__
    ret = await asyncio.shield(exec_coro)
          ^^^^^^^^^^^^^^^^^^^^^^^^^^^^^^^
  File "C:\Users\User\AppData\Local\Programs\Python\Python313\Lib\concurrent\futures\thread.py", line 59, in run
    result = self.fn(*self.args, **self.kwargs)
  File "C:\Users\User\Desktop\docs\.venv\Lib\site-packages\asgiref\sync.py", line 522, in thread_handler
    return func(*args, **kwargs)
  File "C:\Users\User\Desktop\docs\.venv\Lib\site-packages\django\views\decorators\csrf.py", line 65, in _view_wrapper
    return view_func(request, *args, **kwargs)
  File "C:\Users\User\Desktop\docs\.venv\Lib\site-packages\django\views\generic\base.py", line 104, in view
    return self.dispatch(request, *args, **kwargs)
           ~~~~~~~~~~~~~^^^^^^^^^^^^^^^^^^^^^^^^^^
  File "C:\Users\User\Desktop\docs\.venv\Lib\site-packages\rest_framework\views.py", line 509, in dispatch
    response = self.handle_exception(exc)
  File "C:\Users\User\Desktop\docs\.venv\Lib\site-packages\rest_framework\views.py", line 469, in handle_exception
    self.raise_uncaught_exception(exc)
    ~~~~~~~~~~~~~~~~~~~~~~~~~~~~~^^^^^
  File "C:\Users\User\Desktop\docs\.venv\Lib\site-packages\rest_framework\views.py", line 480, in raise_uncaught_exception
    raise exc
  File "C:\Users\User\Desktop\docs\.venv\Lib\site-packages\rest_framework\views.py", line 506, in dispatch
    response = handler(request, *args, **kwargs)
  File "C:\Users\User\Desktop\docs\taskmanager\users\views.py", line 58, in post
    logger.warning(f'Неудачный вход {user.email} неверные данные')
                                     ^^^^^^^^^^
AttributeError: 'NoneType' object has no attribute 'email'
ERROR 2025-02-13 17:08:48,527 runserver HTTP POST /users/api/login/ 500 [0.78, 127.0.0.1:55197]
ERROR 2025-02-13 17:09:04,863 log Internal Server Error: /users/api/login/
Traceback (most recent call last):
  File "C:\Users\User\Desktop\docs\.venv\Lib\site-packages\asgiref\sync.py", line 518, in thread_handler
    raise exc_info[1]
  File "C:\Users\User\Desktop\docs\.venv\Lib\site-packages\django\core\handlers\exception.py", line 42, in inner
    response = await get_response(request)
               ^^^^^^^^^^^^^^^^^^^^^^^^^^^
  File "C:\Users\User\Desktop\docs\.venv\Lib\site-packages\asgiref\sync.py", line 518, in thread_handler
    raise exc_info[1]
  File "C:\Users\User\Desktop\docs\.venv\Lib\site-packages\django\core\handlers\base.py", line 253, in _get_response_async
    response = await wrapped_callback(
               ^^^^^^^^^^^^^^^^^^^^^^^
        request, *callback_args, **callback_kwargs
        ^^^^^^^^^^^^^^^^^^^^^^^^^^^^^^^^^^^^^^^^^^
    )
    ^
  File "C:\Users\User\Desktop\docs\.venv\Lib\site-packages\asgiref\sync.py", line 468, in __call__
    ret = await asyncio.shield(exec_coro)
          ^^^^^^^^^^^^^^^^^^^^^^^^^^^^^^^
  File "C:\Users\User\AppData\Local\Programs\Python\Python313\Lib\concurrent\futures\thread.py", line 59, in run
    result = self.fn(*self.args, **self.kwargs)
  File "C:\Users\User\Desktop\docs\.venv\Lib\site-packages\asgiref\sync.py", line 522, in thread_handler
    return func(*args, **kwargs)
  File "C:\Users\User\Desktop\docs\.venv\Lib\site-packages\django\views\decorators\csrf.py", line 65, in _view_wrapper
    return view_func(request, *args, **kwargs)
  File "C:\Users\User\Desktop\docs\.venv\Lib\site-packages\django\views\generic\base.py", line 104, in view
    return self.dispatch(request, *args, **kwargs)
           ~~~~~~~~~~~~~^^^^^^^^^^^^^^^^^^^^^^^^^^
  File "C:\Users\User\Desktop\docs\.venv\Lib\site-packages\rest_framework\views.py", line 509, in dispatch
    response = self.handle_exception(exc)
  File "C:\Users\User\Desktop\docs\.venv\Lib\site-packages\rest_framework\views.py", line 469, in handle_exception
    self.raise_uncaught_exception(exc)
    ~~~~~~~~~~~~~~~~~~~~~~~~~~~~~^^^^^
  File "C:\Users\User\Desktop\docs\.venv\Lib\site-packages\rest_framework\views.py", line 480, in raise_uncaught_exception
    raise exc
  File "C:\Users\User\Desktop\docs\.venv\Lib\site-packages\rest_framework\views.py", line 506, in dispatch
    response = handler(request, *args, **kwargs)
  File "C:\Users\User\Desktop\docs\taskmanager\users\views.py", line 58, in post
    logger.warning(f'Неудачный вход {user.email} неверные данные')
                                     ^^^^^^^^^^
AttributeError: 'NoneType' object has no attribute 'email'
ERROR 2025-02-13 17:09:04,866 runserver HTTP POST /users/api/login/ 500 [0.74, 127.0.0.1:55197]
ERROR 2025-02-13 17:09:17,871 log Internal Server Error: /users/api/login/
Traceback (most recent call last):
  File "C:\Users\User\Desktop\docs\.venv\Lib\site-packages\asgiref\sync.py", line 518, in thread_handler
    raise exc_info[1]
  File "C:\Users\User\Desktop\docs\.venv\Lib\site-packages\django\core\handlers\exception.py", line 42, in inner
    response = await get_response(request)
               ^^^^^^^^^^^^^^^^^^^^^^^^^^^
  File "C:\Users\User\Desktop\docs\.venv\Lib\site-packages\asgiref\sync.py", line 518, in thread_handler
    raise exc_info[1]
  File "C:\Users\User\Desktop\docs\.venv\Lib\site-packages\django\core\handlers\base.py", line 253, in _get_response_async
    response = await wrapped_callback(
               ^^^^^^^^^^^^^^^^^^^^^^^
        request, *callback_args, **callback_kwargs
        ^^^^^^^^^^^^^^^^^^^^^^^^^^^^^^^^^^^^^^^^^^
    )
    ^
  File "C:\Users\User\Desktop\docs\.venv\Lib\site-packages\asgiref\sync.py", line 468, in __call__
    ret = await asyncio.shield(exec_coro)
          ^^^^^^^^^^^^^^^^^^^^^^^^^^^^^^^
  File "C:\Users\User\AppData\Local\Programs\Python\Python313\Lib\concurrent\futures\thread.py", line 59, in run
    result = self.fn(*self.args, **self.kwargs)
  File "C:\Users\User\Desktop\docs\.venv\Lib\site-packages\asgiref\sync.py", line 522, in thread_handler
    return func(*args, **kwargs)
  File "C:\Users\User\Desktop\docs\.venv\Lib\site-packages\django\views\decorators\csrf.py", line 65, in _view_wrapper
    return view_func(request, *args, **kwargs)
  File "C:\Users\User\Desktop\docs\.venv\Lib\site-packages\django\views\generic\base.py", line 104, in view
    return self.dispatch(request, *args, **kwargs)
           ~~~~~~~~~~~~~^^^^^^^^^^^^^^^^^^^^^^^^^^
  File "C:\Users\User\Desktop\docs\.venv\Lib\site-packages\rest_framework\views.py", line 509, in dispatch
    response = self.handle_exception(exc)
  File "C:\Users\User\Desktop\docs\.venv\Lib\site-packages\rest_framework\views.py", line 469, in handle_exception
    self.raise_uncaught_exception(exc)
    ~~~~~~~~~~~~~~~~~~~~~~~~~~~~~^^^^^
  File "C:\Users\User\Desktop\docs\.venv\Lib\site-packages\rest_framework\views.py", line 480, in raise_uncaught_exception
    raise exc
  File "C:\Users\User\Desktop\docs\.venv\Lib\site-packages\rest_framework\views.py", line 506, in dispatch
    response = handler(request, *args, **kwargs)
  File "C:\Users\User\Desktop\docs\taskmanager\users\views.py", line 58, in post
    logger.warning(f'Неудачный вход {user.email} неверные данные')
                                     ^^^^^^^^^^
AttributeError: 'NoneType' object has no attribute 'email'
ERROR 2025-02-13 17:09:17,877 runserver HTTP POST /users/api/login/ 500 [0.79, 127.0.0.1:55215]
ERROR 2025-02-13 17:10:22,183 log Internal Server Error: /users/api/register/
Traceback (most recent call last):
  File "C:\Users\User\Desktop\docs\.venv\Lib\site-packages\asgiref\sync.py", line 518, in thread_handler
    raise exc_info[1]
  File "C:\Users\User\Desktop\docs\.venv\Lib\site-packages\django\core\handlers\exception.py", line 42, in inner
    response = await get_response(request)
               ^^^^^^^^^^^^^^^^^^^^^^^^^^^
  File "C:\Users\User\Desktop\docs\.venv\Lib\site-packages\asgiref\sync.py", line 518, in thread_handler
    raise exc_info[1]
  File "C:\Users\User\Desktop\docs\.venv\Lib\site-packages\django\core\handlers\base.py", line 253, in _get_response_async
    response = await wrapped_callback(
               ^^^^^^^^^^^^^^^^^^^^^^^
        request, *callback_args, **callback_kwargs
        ^^^^^^^^^^^^^^^^^^^^^^^^^^^^^^^^^^^^^^^^^^
    )
    ^
  File "C:\Users\User\Desktop\docs\.venv\Lib\site-packages\asgiref\sync.py", line 468, in __call__
    ret = await asyncio.shield(exec_coro)
          ^^^^^^^^^^^^^^^^^^^^^^^^^^^^^^^
  File "C:\Users\User\AppData\Local\Programs\Python\Python313\Lib\concurrent\futures\thread.py", line 59, in run
    result = self.fn(*self.args, **self.kwargs)
  File "C:\Users\User\Desktop\docs\.venv\Lib\site-packages\asgiref\sync.py", line 522, in thread_handler
    return func(*args, **kwargs)
  File "C:\Users\User\Desktop\docs\.venv\Lib\site-packages\django\views\decorators\csrf.py", line 65, in _view_wrapper
    return view_func(request, *args, **kwargs)
  File "C:\Users\User\Desktop\docs\.venv\Lib\site-packages\django\views\generic\base.py", line 104, in view
    return self.dispatch(request, *args, **kwargs)
           ~~~~~~~~~~~~~^^^^^^^^^^^^^^^^^^^^^^^^^^
  File "C:\Users\User\Desktop\docs\.venv\Lib\site-packages\rest_framework\views.py", line 509, in dispatch
    response = self.handle_exception(exc)
  File "C:\Users\User\Desktop\docs\.venv\Lib\site-packages\rest_framework\views.py", line 469, in handle_exception
    self.raise_uncaught_exception(exc)
    ~~~~~~~~~~~~~~~~~~~~~~~~~~~~~^^^^^
  File "C:\Users\User\Desktop\docs\.venv\Lib\site-packages\rest_framework\views.py", line 480, in raise_uncaught_exception
    raise exc
  File "C:\Users\User\Desktop\docs\.venv\Lib\site-packages\rest_framework\views.py", line 506, in dispatch
    response = handler(request, *args, **kwargs)
  File "C:\Users\User\Desktop\docs\taskmanager\users\views.py", line 40, in post
    user = User.objects.create_user(**serializer.validated_data)
TypeError: UserCustomManager.create_user() missing 1 required positional argument: 'phone_number'
ERROR 2025-02-13 17:10:22,186 runserver HTTP POST /users/api/register/ 500 [0.08, 127.0.0.1:55220]
WARNING 2025-02-13 17:10:39,594 log Method Not Allowed: /users/api/register/
WARNING 2025-02-13 17:10:39,595 runserver HTTP GET /users/api/register/ 405 [0.08, 127.0.0.1:55225]
ERROR 2025-02-13 17:10:50,048 log Internal Server Error: /users/api/register/
Traceback (most recent call last):
  File "C:\Users\User\Desktop\docs\.venv\Lib\site-packages\asgiref\sync.py", line 518, in thread_handler
    raise exc_info[1]
  File "C:\Users\User\Desktop\docs\.venv\Lib\site-packages\django\core\handlers\exception.py", line 42, in inner
    response = await get_response(request)
               ^^^^^^^^^^^^^^^^^^^^^^^^^^^
  File "C:\Users\User\Desktop\docs\.venv\Lib\site-packages\asgiref\sync.py", line 518, in thread_handler
    raise exc_info[1]
  File "C:\Users\User\Desktop\docs\.venv\Lib\site-packages\django\core\handlers\base.py", line 253, in _get_response_async
    response = await wrapped_callback(
               ^^^^^^^^^^^^^^^^^^^^^^^
        request, *callback_args, **callback_kwargs
        ^^^^^^^^^^^^^^^^^^^^^^^^^^^^^^^^^^^^^^^^^^
    )
    ^
  File "C:\Users\User\Desktop\docs\.venv\Lib\site-packages\asgiref\sync.py", line 468, in __call__
    ret = await asyncio.shield(exec_coro)
          ^^^^^^^^^^^^^^^^^^^^^^^^^^^^^^^
  File "C:\Users\User\AppData\Local\Programs\Python\Python313\Lib\concurrent\futures\thread.py", line 59, in run
    result = self.fn(*self.args, **self.kwargs)
  File "C:\Users\User\Desktop\docs\.venv\Lib\site-packages\asgiref\sync.py", line 522, in thread_handler
    return func(*args, **kwargs)
  File "C:\Users\User\Desktop\docs\.venv\Lib\site-packages\django\views\decorators\csrf.py", line 65, in _view_wrapper
    return view_func(request, *args, **kwargs)
  File "C:\Users\User\Desktop\docs\.venv\Lib\site-packages\django\views\generic\base.py", line 104, in view
    return self.dispatch(request, *args, **kwargs)
           ~~~~~~~~~~~~~^^^^^^^^^^^^^^^^^^^^^^^^^^
  File "C:\Users\User\Desktop\docs\.venv\Lib\site-packages\rest_framework\views.py", line 509, in dispatch
    response = self.handle_exception(exc)
  File "C:\Users\User\Desktop\docs\.venv\Lib\site-packages\rest_framework\views.py", line 469, in handle_exception
    self.raise_uncaught_exception(exc)
    ~~~~~~~~~~~~~~~~~~~~~~~~~~~~~^^^^^
  File "C:\Users\User\Desktop\docs\.venv\Lib\site-packages\rest_framework\views.py", line 480, in raise_uncaught_exception
    raise exc
  File "C:\Users\User\Desktop\docs\.venv\Lib\site-packages\rest_framework\views.py", line 506, in dispatch
    response = handler(request, *args, **kwargs)
  File "C:\Users\User\Desktop\docs\taskmanager\users\views.py", line 40, in post
    user = User.objects.create_user(**serializer.validated_data)
TypeError: UserCustomManager.create_user() missing 1 required positional argument: 'phone_number'
ERROR 2025-02-13 17:10:50,052 runserver HTTP POST /users/api/register/ 500 [0.18, 127.0.0.1:55231]
WARNING 2025-02-13 17:11:23,349 log Bad Request: /users/api/register/
WARNING 2025-02-13 17:11:23,350 runserver HTTP POST /users/api/register/ 400 [0.01, 127.0.0.1:55235]
WARNING 2025-02-13 17:11:42,402 log Bad Request: /users/api/register/
WARNING 2025-02-13 17:11:42,402 runserver HTTP POST /users/api/register/ 400 [0.00, 127.0.0.1:55235]
WARNING 2025-02-13 17:11:51,197 log Bad Request: /users/api/register/
WARNING 2025-02-13 17:11:51,197 runserver HTTP POST /users/api/register/ 400 [0.07, 127.0.0.1:55235]
ERROR 2025-02-13 17:11:58,760 log Internal Server Error: /users/api/register/
Traceback (most recent call last):
  File "C:\Users\User\Desktop\docs\.venv\Lib\site-packages\asgiref\sync.py", line 518, in thread_handler
    raise exc_info[1]
  File "C:\Users\User\Desktop\docs\.venv\Lib\site-packages\django\core\handlers\exception.py", line 42, in inner
    response = await get_response(request)
               ^^^^^^^^^^^^^^^^^^^^^^^^^^^
  File "C:\Users\User\Desktop\docs\.venv\Lib\site-packages\asgiref\sync.py", line 518, in thread_handler
    raise exc_info[1]
  File "C:\Users\User\Desktop\docs\.venv\Lib\site-packages\django\core\handlers\base.py", line 253, in _get_response_async
    response = await wrapped_callback(
               ^^^^^^^^^^^^^^^^^^^^^^^
        request, *callback_args, **callback_kwargs
        ^^^^^^^^^^^^^^^^^^^^^^^^^^^^^^^^^^^^^^^^^^
    )
    ^
  File "C:\Users\User\Desktop\docs\.venv\Lib\site-packages\asgiref\sync.py", line 468, in __call__
    ret = await asyncio.shield(exec_coro)
          ^^^^^^^^^^^^^^^^^^^^^^^^^^^^^^^
  File "C:\Users\User\AppData\Local\Programs\Python\Python313\Lib\concurrent\futures\thread.py", line 59, in run
    result = self.fn(*self.args, **self.kwargs)
  File "C:\Users\User\Desktop\docs\.venv\Lib\site-packages\asgiref\sync.py", line 522, in thread_handler
    return func(*args, **kwargs)
  File "C:\Users\User\Desktop\docs\.venv\Lib\site-packages\django\views\decorators\csrf.py", line 65, in _view_wrapper
    return view_func(request, *args, **kwargs)
  File "C:\Users\User\Desktop\docs\.venv\Lib\site-packages\django\views\generic\base.py", line 104, in view
    return self.dispatch(request, *args, **kwargs)
           ~~~~~~~~~~~~~^^^^^^^^^^^^^^^^^^^^^^^^^^
  File "C:\Users\User\Desktop\docs\.venv\Lib\site-packages\rest_framework\views.py", line 509, in dispatch
    response = self.handle_exception(exc)
  File "C:\Users\User\Desktop\docs\.venv\Lib\site-packages\rest_framework\views.py", line 469, in handle_exception
    self.raise_uncaught_exception(exc)
    ~~~~~~~~~~~~~~~~~~~~~~~~~~~~~^^^^^
  File "C:\Users\User\Desktop\docs\.venv\Lib\site-packages\rest_framework\views.py", line 480, in raise_uncaught_exception
    raise exc
  File "C:\Users\User\Desktop\docs\.venv\Lib\site-packages\rest_framework\views.py", line 506, in dispatch
    response = handler(request, *args, **kwargs)
  File "C:\Users\User\Desktop\docs\taskmanager\users\views.py", line 40, in post
    user = User.objects.create_user(**serializer.validated_data)
TypeError: UserCustomManager.create_user() missing 1 required positional argument: 'phone_number'
ERROR 2025-02-13 17:11:58,765 runserver HTTP POST /users/api/register/ 500 [0.22, 127.0.0.1:55235]
ERROR 2025-02-13 17:15:31,679 runserver HTTP POST /users/api/register/ 500 [0.12, 127.0.0.1:55261]
ERROR 2025-02-13 17:16:05,877 log Internal Server Error: /users/api/register/
Traceback (most recent call last):
  File "C:\Users\User\Desktop\docs\.venv\Lib\site-packages\asgiref\sync.py", line 518, in thread_handler
    raise exc_info[1]
  File "C:\Users\User\Desktop\docs\.venv\Lib\site-packages\django\core\handlers\exception.py", line 42, in inner
    response = await get_response(request)
               ^^^^^^^^^^^^^^^^^^^^^^^^^^^
  File "C:\Users\User\Desktop\docs\.venv\Lib\site-packages\asgiref\sync.py", line 518, in thread_handler
    raise exc_info[1]
  File "C:\Users\User\Desktop\docs\.venv\Lib\site-packages\django\core\handlers\base.py", line 253, in _get_response_async
    response = await wrapped_callback(
               ^^^^^^^^^^^^^^^^^^^^^^^
        request, *callback_args, **callback_kwargs
        ^^^^^^^^^^^^^^^^^^^^^^^^^^^^^^^^^^^^^^^^^^
    )
    ^
  File "C:\Users\User\Desktop\docs\.venv\Lib\site-packages\asgiref\sync.py", line 468, in __call__
    ret = await asyncio.shield(exec_coro)
          ^^^^^^^^^^^^^^^^^^^^^^^^^^^^^^^
  File "C:\Users\User\AppData\Local\Programs\Python\Python313\Lib\concurrent\futures\thread.py", line 59, in run
    result = self.fn(*self.args, **self.kwargs)
  File "C:\Users\User\Desktop\docs\.venv\Lib\site-packages\asgiref\sync.py", line 522, in thread_handler
    return func(*args, **kwargs)
  File "C:\Users\User\Desktop\docs\.venv\Lib\site-packages\django\views\decorators\csrf.py", line 65, in _view_wrapper
    return view_func(request, *args, **kwargs)
  File "C:\Users\User\Desktop\docs\.venv\Lib\site-packages\django\views\generic\base.py", line 104, in view
    return self.dispatch(request, *args, **kwargs)
           ~~~~~~~~~~~~~^^^^^^^^^^^^^^^^^^^^^^^^^^
  File "C:\Users\User\Desktop\docs\.venv\Lib\site-packages\rest_framework\views.py", line 509, in dispatch
    response = self.handle_exception(exc)
  File "C:\Users\User\Desktop\docs\.venv\Lib\site-packages\rest_framework\views.py", line 469, in handle_exception
    self.raise_uncaught_exception(exc)
    ~~~~~~~~~~~~~~~~~~~~~~~~~~~~~^^^^^
  File "C:\Users\User\Desktop\docs\.venv\Lib\site-packages\rest_framework\views.py", line 480, in raise_uncaught_exception
    raise exc
  File "C:\Users\User\Desktop\docs\.venv\Lib\site-packages\rest_framework\views.py", line 506, in dispatch
    response = handler(request, *args, **kwargs)
  File "C:\Users\User\Desktop\docs\taskmanager\users\views.py", line 40, in post
    user = User.objects.create_user(**serializer.validated_data)
TypeError: UserCustomManager.create_user() missing 1 required positional argument: 'phone_number'
ERROR 2025-02-13 17:16:05,882 runserver HTTP POST /users/api/register/ 500 [0.08, 127.0.0.1:55275]
WARNING 2025-02-13 17:16:28,619 log Method Not Allowed: /users/api/register/
WARNING 2025-02-13 17:16:28,620 runserver HTTP GET /users/api/register/ 405 [0.22, 127.0.0.1:55278]
ERROR 2025-02-13 17:16:35,299 log Internal Server Error: /users/api/register/
Traceback (most recent call last):
  File "C:\Users\User\Desktop\docs\.venv\Lib\site-packages\asgiref\sync.py", line 518, in thread_handler
    raise exc_info[1]
  File "C:\Users\User\Desktop\docs\.venv\Lib\site-packages\django\core\handlers\exception.py", line 42, in inner
    response = await get_response(request)
               ^^^^^^^^^^^^^^^^^^^^^^^^^^^
  File "C:\Users\User\Desktop\docs\.venv\Lib\site-packages\asgiref\sync.py", line 518, in thread_handler
    raise exc_info[1]
  File "C:\Users\User\Desktop\docs\.venv\Lib\site-packages\django\core\handlers\base.py", line 253, in _get_response_async
    response = await wrapped_callback(
               ^^^^^^^^^^^^^^^^^^^^^^^
        request, *callback_args, **callback_kwargs
        ^^^^^^^^^^^^^^^^^^^^^^^^^^^^^^^^^^^^^^^^^^
    )
    ^
  File "C:\Users\User\Desktop\docs\.venv\Lib\site-packages\asgiref\sync.py", line 468, in __call__
    ret = await asyncio.shield(exec_coro)
          ^^^^^^^^^^^^^^^^^^^^^^^^^^^^^^^
  File "C:\Users\User\AppData\Local\Programs\Python\Python313\Lib\concurrent\futures\thread.py", line 59, in run
    result = self.fn(*self.args, **self.kwargs)
  File "C:\Users\User\Desktop\docs\.venv\Lib\site-packages\asgiref\sync.py", line 522, in thread_handler
    return func(*args, **kwargs)
  File "C:\Users\User\Desktop\docs\.venv\Lib\site-packages\django\views\decorators\csrf.py", line 65, in _view_wrapper
    return view_func(request, *args, **kwargs)
  File "C:\Users\User\Desktop\docs\.venv\Lib\site-packages\django\views\generic\base.py", line 104, in view
    return self.dispatch(request, *args, **kwargs)
           ~~~~~~~~~~~~~^^^^^^^^^^^^^^^^^^^^^^^^^^
  File "C:\Users\User\Desktop\docs\.venv\Lib\site-packages\rest_framework\views.py", line 509, in dispatch
    response = self.handle_exception(exc)
  File "C:\Users\User\Desktop\docs\.venv\Lib\site-packages\rest_framework\views.py", line 469, in handle_exception
    self.raise_uncaught_exception(exc)
    ~~~~~~~~~~~~~~~~~~~~~~~~~~~~~^^^^^
  File "C:\Users\User\Desktop\docs\.venv\Lib\site-packages\rest_framework\views.py", line 480, in raise_uncaught_exception
    raise exc
  File "C:\Users\User\Desktop\docs\.venv\Lib\site-packages\rest_framework\views.py", line 506, in dispatch
    response = handler(request, *args, **kwargs)
  File "C:\Users\User\Desktop\docs\taskmanager\users\views.py", line 40, in post
    user = User.objects.create_user(**serializer.validated_data)
TypeError: UserCustomManager.create_user() missing 1 required positional argument: 'phone_number'
ERROR 2025-02-13 17:16:35,302 runserver HTTP POST /users/api/register/ 500 [0.19, 127.0.0.1:55281]
WARNING 2025-02-13 17:17:50,682 log Method Not Allowed: /users/api/register/
WARNING 2025-02-13 17:17:50,682 runserver HTTP GET /users/api/register/ 405 [0.21, 127.0.0.1:55289]
ERROR 2025-02-13 17:17:54,286 log Internal Server Error: /users/api/register/
Traceback (most recent call last):
  File "C:\Users\User\Desktop\docs\.venv\Lib\site-packages\asgiref\sync.py", line 518, in thread_handler
    raise exc_info[1]
  File "C:\Users\User\Desktop\docs\.venv\Lib\site-packages\django\core\handlers\exception.py", line 42, in inner
    response = await get_response(request)
               ^^^^^^^^^^^^^^^^^^^^^^^^^^^
  File "C:\Users\User\Desktop\docs\.venv\Lib\site-packages\asgiref\sync.py", line 518, in thread_handler
    raise exc_info[1]
  File "C:\Users\User\Desktop\docs\.venv\Lib\site-packages\django\core\handlers\base.py", line 253, in _get_response_async
    response = await wrapped_callback(
               ^^^^^^^^^^^^^^^^^^^^^^^
        request, *callback_args, **callback_kwargs
        ^^^^^^^^^^^^^^^^^^^^^^^^^^^^^^^^^^^^^^^^^^
    )
    ^
  File "C:\Users\User\Desktop\docs\.venv\Lib\site-packages\asgiref\sync.py", line 468, in __call__
    ret = await asyncio.shield(exec_coro)
          ^^^^^^^^^^^^^^^^^^^^^^^^^^^^^^^
  File "C:\Users\User\AppData\Local\Programs\Python\Python313\Lib\concurrent\futures\thread.py", line 59, in run
    result = self.fn(*self.args, **self.kwargs)
  File "C:\Users\User\Desktop\docs\.venv\Lib\site-packages\asgiref\sync.py", line 522, in thread_handler
    return func(*args, **kwargs)
  File "C:\Users\User\Desktop\docs\.venv\Lib\site-packages\django\views\decorators\csrf.py", line 65, in _view_wrapper
    return view_func(request, *args, **kwargs)
  File "C:\Users\User\Desktop\docs\.venv\Lib\site-packages\django\views\generic\base.py", line 104, in view
    return self.dispatch(request, *args, **kwargs)
           ~~~~~~~~~~~~~^^^^^^^^^^^^^^^^^^^^^^^^^^
  File "C:\Users\User\Desktop\docs\.venv\Lib\site-packages\rest_framework\views.py", line 509, in dispatch
    response = self.handle_exception(exc)
  File "C:\Users\User\Desktop\docs\.venv\Lib\site-packages\rest_framework\views.py", line 469, in handle_exception
    self.raise_uncaught_exception(exc)
    ~~~~~~~~~~~~~~~~~~~~~~~~~~~~~^^^^^
  File "C:\Users\User\Desktop\docs\.venv\Lib\site-packages\rest_framework\views.py", line 480, in raise_uncaught_exception
    raise exc
  File "C:\Users\User\Desktop\docs\.venv\Lib\site-packages\rest_framework\views.py", line 506, in dispatch
    response = handler(request, *args, **kwargs)
  File "C:\Users\User\Desktop\docs\taskmanager\users\views.py", line 40, in post
    user = User.objects.create_user(**serializer.validated_data)
TypeError: UserCustomManager.create_user() missing 1 required positional argument: 'phone_number'
ERROR 2025-02-13 17:17:54,291 runserver HTTP POST /users/api/register/ 500 [0.08, 127.0.0.1:55289]
ERROR 2025-02-13 17:18:21,822 log Internal Server Error: /users/api/register/
Traceback (most recent call last):
  File "C:\Users\User\Desktop\docs\.venv\Lib\site-packages\asgiref\sync.py", line 518, in thread_handler
    raise exc_info[1]
  File "C:\Users\User\Desktop\docs\.venv\Lib\site-packages\django\core\handlers\exception.py", line 42, in inner
    response = await get_response(request)
               ^^^^^^^^^^^^^^^^^^^^^^^^^^^
  File "C:\Users\User\Desktop\docs\.venv\Lib\site-packages\asgiref\sync.py", line 518, in thread_handler
    raise exc_info[1]
  File "C:\Users\User\Desktop\docs\.venv\Lib\site-packages\django\core\handlers\base.py", line 253, in _get_response_async
    response = await wrapped_callback(
               ^^^^^^^^^^^^^^^^^^^^^^^
        request, *callback_args, **callback_kwargs
        ^^^^^^^^^^^^^^^^^^^^^^^^^^^^^^^^^^^^^^^^^^
    )
    ^
  File "C:\Users\User\Desktop\docs\.venv\Lib\site-packages\asgiref\sync.py", line 468, in __call__
    ret = await asyncio.shield(exec_coro)
          ^^^^^^^^^^^^^^^^^^^^^^^^^^^^^^^
  File "C:\Users\User\AppData\Local\Programs\Python\Python313\Lib\concurrent\futures\thread.py", line 59, in run
    result = self.fn(*self.args, **self.kwargs)
  File "C:\Users\User\Desktop\docs\.venv\Lib\site-packages\asgiref\sync.py", line 522, in thread_handler
    return func(*args, **kwargs)
  File "C:\Users\User\Desktop\docs\.venv\Lib\site-packages\django\views\decorators\csrf.py", line 65, in _view_wrapper
    return view_func(request, *args, **kwargs)
  File "C:\Users\User\Desktop\docs\.venv\Lib\site-packages\django\views\generic\base.py", line 104, in view
    return self.dispatch(request, *args, **kwargs)
           ~~~~~~~~~~~~~^^^^^^^^^^^^^^^^^^^^^^^^^^
  File "C:\Users\User\Desktop\docs\.venv\Lib\site-packages\rest_framework\views.py", line 509, in dispatch
    response = self.handle_exception(exc)
  File "C:\Users\User\Desktop\docs\.venv\Lib\site-packages\rest_framework\views.py", line 469, in handle_exception
    self.raise_uncaught_exception(exc)
    ~~~~~~~~~~~~~~~~~~~~~~~~~~~~~^^^^^
  File "C:\Users\User\Desktop\docs\.venv\Lib\site-packages\rest_framework\views.py", line 480, in raise_uncaught_exception
    raise exc
  File "C:\Users\User\Desktop\docs\.venv\Lib\site-packages\rest_framework\views.py", line 506, in dispatch
    response = handler(request, *args, **kwargs)
  File "C:\Users\User\Desktop\docs\taskmanager\users\views.py", line 40, in post
    user = User.objects.create_user(**serializer.validated_data)
TypeError: UserCustomManager.create_user() missing 1 required positional argument: 'phone_number'
ERROR 2025-02-13 17:18:21,825 runserver HTTP POST /users/api/register/ 500 [0.21, 127.0.0.1:55289]
WARNING 2025-02-13 17:18:48,457 log Method Not Allowed: /users/api/register/
WARNING 2025-02-13 17:18:48,457 runserver HTTP GET /users/api/register/ 405 [0.06, 127.0.0.1:55289]
ERROR 2025-02-13 17:19:17,239 log Internal Server Error: /users/api/register/
Traceback (most recent call last):
  File "C:\Users\User\Desktop\docs\.venv\Lib\site-packages\asgiref\sync.py", line 518, in thread_handler
    raise exc_info[1]
  File "C:\Users\User\Desktop\docs\.venv\Lib\site-packages\django\core\handlers\exception.py", line 42, in inner
    response = await get_response(request)
               ^^^^^^^^^^^^^^^^^^^^^^^^^^^
  File "C:\Users\User\Desktop\docs\.venv\Lib\site-packages\asgiref\sync.py", line 518, in thread_handler
    raise exc_info[1]
  File "C:\Users\User\Desktop\docs\.venv\Lib\site-packages\django\core\handlers\base.py", line 253, in _get_response_async
    response = await wrapped_callback(
               ^^^^^^^^^^^^^^^^^^^^^^^
        request, *callback_args, **callback_kwargs
        ^^^^^^^^^^^^^^^^^^^^^^^^^^^^^^^^^^^^^^^^^^
    )
    ^
  File "C:\Users\User\Desktop\docs\.venv\Lib\site-packages\asgiref\sync.py", line 468, in __call__
    ret = await asyncio.shield(exec_coro)
          ^^^^^^^^^^^^^^^^^^^^^^^^^^^^^^^
  File "C:\Users\User\AppData\Local\Programs\Python\Python313\Lib\concurrent\futures\thread.py", line 59, in run
    result = self.fn(*self.args, **self.kwargs)
  File "C:\Users\User\Desktop\docs\.venv\Lib\site-packages\asgiref\sync.py", line 522, in thread_handler
    return func(*args, **kwargs)
  File "C:\Users\User\Desktop\docs\.venv\Lib\site-packages\django\views\decorators\csrf.py", line 65, in _view_wrapper
    return view_func(request, *args, **kwargs)
  File "C:\Users\User\Desktop\docs\.venv\Lib\site-packages\django\views\generic\base.py", line 104, in view
    return self.dispatch(request, *args, **kwargs)
           ~~~~~~~~~~~~~^^^^^^^^^^^^^^^^^^^^^^^^^^
  File "C:\Users\User\Desktop\docs\.venv\Lib\site-packages\rest_framework\views.py", line 509, in dispatch
    response = self.handle_exception(exc)
  File "C:\Users\User\Desktop\docs\.venv\Lib\site-packages\rest_framework\views.py", line 469, in handle_exception
    self.raise_uncaught_exception(exc)
    ~~~~~~~~~~~~~~~~~~~~~~~~~~~~~^^^^^
  File "C:\Users\User\Desktop\docs\.venv\Lib\site-packages\rest_framework\views.py", line 480, in raise_uncaught_exception
    raise exc
  File "C:\Users\User\Desktop\docs\.venv\Lib\site-packages\rest_framework\views.py", line 506, in dispatch
    response = handler(request, *args, **kwargs)
  File "C:\Users\User\Desktop\docs\taskmanager\users\views.py", line 40, in post
    user = User.objects.create_user(**serializer.validated_data)
TypeError: UserCustomManager.create_user() missing 1 required positional argument: 'phone_number'
ERROR 2025-02-13 17:19:17,242 runserver HTTP POST /users/api/register/ 500 [0.18, 127.0.0.1:55289]
WARNING 2025-02-13 17:19:23,163 log Not Found: /
WARNING 2025-02-13 17:19:23,163 runserver HTTP GET / 404 [0.04, 127.0.0.1:55289]
WARNING 2025-02-13 17:19:45,873 log Method Not Allowed: /users/api/register/
WARNING 2025-02-13 17:19:45,873 runserver HTTP GET /users/api/register/ 405 [0.18, 127.0.0.1:55303]
ERROR 2025-02-13 17:19:49,833 log Internal Server Error: /users/api/register/
Traceback (most recent call last):
  File "C:\Users\User\Desktop\docs\.venv\Lib\site-packages\asgiref\sync.py", line 518, in thread_handler
    raise exc_info[1]
  File "C:\Users\User\Desktop\docs\.venv\Lib\site-packages\django\core\handlers\exception.py", line 42, in inner
    response = await get_response(request)
               ^^^^^^^^^^^^^^^^^^^^^^^^^^^
  File "C:\Users\User\Desktop\docs\.venv\Lib\site-packages\asgiref\sync.py", line 518, in thread_handler
    raise exc_info[1]
  File "C:\Users\User\Desktop\docs\.venv\Lib\site-packages\django\core\handlers\base.py", line 253, in _get_response_async
    response = await wrapped_callback(
               ^^^^^^^^^^^^^^^^^^^^^^^
        request, *callback_args, **callback_kwargs
        ^^^^^^^^^^^^^^^^^^^^^^^^^^^^^^^^^^^^^^^^^^
    )
    ^
  File "C:\Users\User\Desktop\docs\.venv\Lib\site-packages\asgiref\sync.py", line 468, in __call__
    ret = await asyncio.shield(exec_coro)
          ^^^^^^^^^^^^^^^^^^^^^^^^^^^^^^^
  File "C:\Users\User\AppData\Local\Programs\Python\Python313\Lib\concurrent\futures\thread.py", line 59, in run
    result = self.fn(*self.args, **self.kwargs)
  File "C:\Users\User\Desktop\docs\.venv\Lib\site-packages\asgiref\sync.py", line 522, in thread_handler
    return func(*args, **kwargs)
  File "C:\Users\User\Desktop\docs\.venv\Lib\site-packages\django\views\decorators\csrf.py", line 65, in _view_wrapper
    return view_func(request, *args, **kwargs)
  File "C:\Users\User\Desktop\docs\.venv\Lib\site-packages\django\views\generic\base.py", line 104, in view
    return self.dispatch(request, *args, **kwargs)
           ~~~~~~~~~~~~~^^^^^^^^^^^^^^^^^^^^^^^^^^
  File "C:\Users\User\Desktop\docs\.venv\Lib\site-packages\rest_framework\views.py", line 509, in dispatch
    response = self.handle_exception(exc)
  File "C:\Users\User\Desktop\docs\.venv\Lib\site-packages\rest_framework\views.py", line 469, in handle_exception
    self.raise_uncaught_exception(exc)
    ~~~~~~~~~~~~~~~~~~~~~~~~~~~~~^^^^^
  File "C:\Users\User\Desktop\docs\.venv\Lib\site-packages\rest_framework\views.py", line 480, in raise_uncaught_exception
    raise exc
  File "C:\Users\User\Desktop\docs\.venv\Lib\site-packages\rest_framework\views.py", line 506, in dispatch
    response = handler(request, *args, **kwargs)
  File "C:\Users\User\Desktop\docs\taskmanager\users\views.py", line 40, in post
    user = User.objects.create_user(**serializer.validated_data)
TypeError: UserCustomManager.create_user() missing 1 required positional argument: 'phone_number'
ERROR 2025-02-13 17:19:49,837 runserver HTTP POST /users/api/register/ 500 [0.07, 127.0.0.1:55303]
WARNING 2025-02-13 17:20:59,279 log Method Not Allowed: /users/api/register/
WARNING 2025-02-13 17:20:59,280 runserver HTTP GET /users/api/register/ 405 [0.09, 127.0.0.1:55333]
ERROR 2025-02-13 17:21:05,279 runserver HTTP POST /users/api/register/ 500 [0.09, 127.0.0.1:55333]
WARNING 2025-02-13 17:21:11,411 log Not Found: /
WARNING 2025-02-13 17:21:11,411 runserver HTTP GET / 404 [0.01, 127.0.0.1:55333]
ERROR 2025-02-13 17:23:34,670 log Internal Server Error: /users/api/login/
Traceback (most recent call last):
  File "C:\Users\User\Desktop\docs\.venv\Lib\site-packages\asgiref\sync.py", line 518, in thread_handler
    raise exc_info[1]
  File "C:\Users\User\Desktop\docs\.venv\Lib\site-packages\django\core\handlers\exception.py", line 42, in inner
    response = await get_response(request)
               ^^^^^^^^^^^^^^^^^^^^^^^^^^^
  File "C:\Users\User\Desktop\docs\.venv\Lib\site-packages\asgiref\sync.py", line 518, in thread_handler
    raise exc_info[1]
  File "C:\Users\User\Desktop\docs\.venv\Lib\site-packages\django\core\handlers\base.py", line 253, in _get_response_async
    response = await wrapped_callback(
               ^^^^^^^^^^^^^^^^^^^^^^^
        request, *callback_args, **callback_kwargs
        ^^^^^^^^^^^^^^^^^^^^^^^^^^^^^^^^^^^^^^^^^^
    )
    ^
  File "C:\Users\User\Desktop\docs\.venv\Lib\site-packages\asgiref\sync.py", line 468, in __call__
    ret = await asyncio.shield(exec_coro)
          ^^^^^^^^^^^^^^^^^^^^^^^^^^^^^^^
  File "C:\Users\User\AppData\Local\Programs\Python\Python313\Lib\concurrent\futures\thread.py", line 59, in run
    result = self.fn(*self.args, **self.kwargs)
  File "C:\Users\User\Desktop\docs\.venv\Lib\site-packages\asgiref\sync.py", line 522, in thread_handler
    return func(*args, **kwargs)
  File "C:\Users\User\Desktop\docs\.venv\Lib\site-packages\django\views\decorators\csrf.py", line 65, in _view_wrapper
    return view_func(request, *args, **kwargs)
  File "C:\Users\User\Desktop\docs\.venv\Lib\site-packages\django\views\generic\base.py", line 104, in view
    return self.dispatch(request, *args, **kwargs)
           ~~~~~~~~~~~~~^^^^^^^^^^^^^^^^^^^^^^^^^^
  File "C:\Users\User\Desktop\docs\.venv\Lib\site-packages\rest_framework\views.py", line 509, in dispatch
    response = self.handle_exception(exc)
  File "C:\Users\User\Desktop\docs\.venv\Lib\site-packages\rest_framework\views.py", line 469, in handle_exception
    self.raise_uncaught_exception(exc)
    ~~~~~~~~~~~~~~~~~~~~~~~~~~~~~^^^^^
  File "C:\Users\User\Desktop\docs\.venv\Lib\site-packages\rest_framework\views.py", line 480, in raise_uncaught_exception
    raise exc
  File "C:\Users\User\Desktop\docs\.venv\Lib\site-packages\rest_framework\views.py", line 506, in dispatch
    response = handler(request, *args, **kwargs)
  File "C:\Users\User\Desktop\docs\taskmanager\users\views.py", line 79, in post
    token = jwt.encode(payload, SECRET, algorithm='HS256')
            ^^^^^^^^^^
AttributeError: module 'jwt' has no attribute 'encode'
ERROR 2025-02-13 17:23:34,674 runserver HTTP POST /users/api/login/ 500 [0.75, 127.0.0.1:55342]
WARNING 2025-02-13 17:23:58,214 log Method Not Allowed: /users/api/login/
WARNING 2025-02-13 17:23:58,215 runserver HTTP GET /users/api/login/ 405 [0.20, 127.0.0.1:55353]
ERROR 2025-02-13 17:24:04,157 log Internal Server Error: /users/api/login/
Traceback (most recent call last):
  File "C:\Users\User\Desktop\docs\.venv\Lib\site-packages\asgiref\sync.py", line 518, in thread_handler
    raise exc_info[1]
  File "C:\Users\User\Desktop\docs\.venv\Lib\site-packages\django\core\handlers\exception.py", line 42, in inner
    response = await get_response(request)
               ^^^^^^^^^^^^^^^^^^^^^^^^^^^
  File "C:\Users\User\Desktop\docs\.venv\Lib\site-packages\asgiref\sync.py", line 518, in thread_handler
    raise exc_info[1]
  File "C:\Users\User\Desktop\docs\.venv\Lib\site-packages\django\core\handlers\base.py", line 253, in _get_response_async
    response = await wrapped_callback(
               ^^^^^^^^^^^^^^^^^^^^^^^
        request, *callback_args, **callback_kwargs
        ^^^^^^^^^^^^^^^^^^^^^^^^^^^^^^^^^^^^^^^^^^
    )
    ^
  File "C:\Users\User\Desktop\docs\.venv\Lib\site-packages\asgiref\sync.py", line 468, in __call__
    ret = await asyncio.shield(exec_coro)
          ^^^^^^^^^^^^^^^^^^^^^^^^^^^^^^^
  File "C:\Users\User\AppData\Local\Programs\Python\Python313\Lib\concurrent\futures\thread.py", line 59, in run
    result = self.fn(*self.args, **self.kwargs)
  File "C:\Users\User\Desktop\docs\.venv\Lib\site-packages\asgiref\sync.py", line 522, in thread_handler
    return func(*args, **kwargs)
  File "C:\Users\User\Desktop\docs\.venv\Lib\site-packages\django\views\decorators\csrf.py", line 65, in _view_wrapper
    return view_func(request, *args, **kwargs)
  File "C:\Users\User\Desktop\docs\.venv\Lib\site-packages\django\views\generic\base.py", line 104, in view
    return self.dispatch(request, *args, **kwargs)
           ~~~~~~~~~~~~~^^^^^^^^^^^^^^^^^^^^^^^^^^
  File "C:\Users\User\Desktop\docs\.venv\Lib\site-packages\rest_framework\views.py", line 509, in dispatch
    response = self.handle_exception(exc)
  File "C:\Users\User\Desktop\docs\.venv\Lib\site-packages\rest_framework\views.py", line 469, in handle_exception
    self.raise_uncaught_exception(exc)
    ~~~~~~~~~~~~~~~~~~~~~~~~~~~~~^^^^^
  File "C:\Users\User\Desktop\docs\.venv\Lib\site-packages\rest_framework\views.py", line 480, in raise_uncaught_exception
    raise exc
  File "C:\Users\User\Desktop\docs\.venv\Lib\site-packages\rest_framework\views.py", line 506, in dispatch
    response = handler(request, *args, **kwargs)
  File "C:\Users\User\Desktop\docs\taskmanager\users\views.py", line 79, in post
    token = jwt.encode(payload, SECRET, algorithm='HS256')
            ^^^^^^^^^^
AttributeError: module 'jwt' has no attribute 'encode'
ERROR 2025-02-13 17:24:04,161 runserver HTTP POST /users/api/login/ 500 [0.70, 127.0.0.1:55359]
WARNING 2025-02-13 17:28:05,676 log Method Not Allowed: /users/api/login/
WARNING 2025-02-13 17:28:05,677 runserver HTTP GET /users/api/login/ 405 [0.11, 127.0.0.1:55393]
WARNING 2025-02-13 17:28:56,086 log Forbidden: /users/api/login/
WARNING 2025-02-13 17:28:56,086 runserver HTTP POST /users/api/login/ 403 [0.01, 127.0.0.1:55398]
WARNING 2025-02-14 09:19:06,166 log Not Found: /
WARNING 2025-02-14 09:19:06,167 runserver HTTP GET / 404 [0.06, 127.0.0.1:56109]
WARNING 2025-02-14 09:19:06,301 log Not Found: /favicon.ico
WARNING 2025-02-14 09:19:06,302 runserver HTTP GET /favicon.ico 404 [0.01, 127.0.0.1:56109]
WARNING 2025-02-17 09:14:46,987 log Not Found: /
WARNING 2025-02-17 09:14:46,988 runserver HTTP GET / 404 [0.05, 127.0.0.1:49689]
WARNING 2025-02-17 09:14:47,099 log Not Found: /favicon.ico
WARNING 2025-02-17 09:14:47,100 runserver HTTP GET /favicon.ico 404 [0.02, 127.0.0.1:49689]
ERROR 2025-02-17 09:15:34,190 log Internal Server Error: /admin/reports/reports/add/
Traceback (most recent call last):
  File "C:\Users\User\Desktop\docs\.venv\Lib\site-packages\asgiref\sync.py", line 518, in thread_handler
    raise exc_info[1]
  File "C:\Users\User\Desktop\docs\.venv\Lib\site-packages\django\core\handlers\exception.py", line 42, in inner
    response = await get_response(request)
               ^^^^^^^^^^^^^^^^^^^^^^^^^^^
  File "C:\Users\User\Desktop\docs\.venv\Lib\site-packages\asgiref\sync.py", line 518, in thread_handler
    raise exc_info[1]
  File "C:\Users\User\Desktop\docs\.venv\Lib\site-packages\django\core\handlers\base.py", line 253, in _get_response_async
    response = await wrapped_callback(
               ^^^^^^^^^^^^^^^^^^^^^^^
        request, *callback_args, **callback_kwargs
        ^^^^^^^^^^^^^^^^^^^^^^^^^^^^^^^^^^^^^^^^^^
    )
    ^
  File "C:\Users\User\Desktop\docs\.venv\Lib\site-packages\asgiref\sync.py", line 468, in __call__
    ret = await asyncio.shield(exec_coro)
          ^^^^^^^^^^^^^^^^^^^^^^^^^^^^^^^
  File "C:\Users\User\AppData\Local\Programs\Python\Python313\Lib\concurrent\futures\thread.py", line 59, in run
    result = self.fn(*self.args, **self.kwargs)
  File "C:\Users\User\Desktop\docs\.venv\Lib\site-packages\asgiref\sync.py", line 522, in thread_handler
    return func(*args, **kwargs)
  File "C:\Users\User\Desktop\docs\.venv\Lib\site-packages\django\contrib\admin\options.py", line 718, in wrapper
    return self.admin_site.admin_view(view)(*args, **kwargs)
           ~~~~~~~~~~~~~~~~~~~~~~~~~~~~~~~~^^^^^^^^^^^^^^^^^
  File "C:\Users\User\Desktop\docs\.venv\Lib\site-packages\django\utils\decorators.py", line 188, in _view_wrapper
    result = _process_exception(request, e)
  File "C:\Users\User\Desktop\docs\.venv\Lib\site-packages\django\utils\decorators.py", line 186, in _view_wrapper
    response = view_func(request, *args, **kwargs)
  File "C:\Users\User\Desktop\docs\.venv\Lib\site-packages\django\views\decorators\cache.py", line 80, in _view_wrapper
    response = view_func(request, *args, **kwargs)
  File "C:\Users\User\Desktop\docs\.venv\Lib\site-packages\django\contrib\admin\sites.py", line 241, in inner
    return view(request, *args, **kwargs)
  File "C:\Users\User\Desktop\docs\.venv\Lib\site-packages\django\contrib\admin\options.py", line 1961, in add_view
    return self.changeform_view(request, None, form_url, extra_context)
           ~~~~~~~~~~~~~~~~~~~~^^^^^^^^^^^^^^^^^^^^^^^^^^^^^^^^^^^^^^^^
  File "C:\Users\User\Desktop\docs\.venv\Lib\site-packages\django\utils\decorators.py", line 48, in _wrapper
    return bound_method(*args, **kwargs)
  File "C:\Users\User\Desktop\docs\.venv\Lib\site-packages\django\utils\decorators.py", line 188, in _view_wrapper
    result = _process_exception(request, e)
  File "C:\Users\User\Desktop\docs\.venv\Lib\site-packages\django\utils\decorators.py", line 186, in _view_wrapper
    response = view_func(request, *args, **kwargs)
  File "C:\Users\User\Desktop\docs\.venv\Lib\site-packages\django\contrib\admin\options.py", line 1820, in changeform_view
    return self._changeform_view(request, object_id, form_url, extra_context)
           ~~~~~~~~~~~~~~~~~~~~~^^^^^^^^^^^^^^^^^^^^^^^^^^^^^^^^^^^^^^^^^^^^^
  File "C:\Users\User\Desktop\docs\.venv\Lib\site-packages\django\contrib\admin\options.py", line 1865, in _changeform_view
    form_validated = form.is_valid()
  File "C:\Users\User\Desktop\docs\.venv\Lib\site-packages\django\forms\forms.py", line 197, in is_valid
    return self.is_bound and not self.errors
                                 ^^^^^^^^^^^
  File "C:\Users\User\Desktop\docs\.venv\Lib\site-packages\django\forms\forms.py", line 192, in errors
    self.full_clean()
    ~~~~~~~~~~~~~~~^^
  File "C:\Users\User\Desktop\docs\.venv\Lib\site-packages\django\forms\forms.py", line 327, in full_clean
    self._post_clean()
    ~~~~~~~~~~~~~~~~^^
  File "C:\Users\User\Desktop\docs\.venv\Lib\site-packages\django\forms\models.py", line 498, in _post_clean
    self.instance.full_clean(exclude=exclude, validate_unique=False)
    ~~~~~~~~~~~~~~~~~~~~~~~~^^^^^^^^^^^^^^^^^^^^^^^^^^^^^^^^^^^^^^^^
  File "C:\Users\User\Desktop\docs\.venv\Lib\site-packages\django\db\models\base.py", line 1626, in full_clean
    self.clean()
    ~~~~~~~~~~^^
  File "C:\Users\User\Desktop\docs\taskmanager\reports\models.py", line 18, in clean
    if self.start_date and self.end_date and self.start_date >= end_date:
                                                                ^^^^^^^^
NameError: name 'end_date' is not defined. Did you mean: 'self.end_date'?
ERROR 2025-02-17 09:15:34,211 runserver HTTP POST /admin/reports/reports/add/ 500 [0.23, 127.0.0.1:49688]
WARNING 2025-02-17 10:32:05,134 log Not Found: /
WARNING 2025-02-17 10:32:05,136 runserver HTTP GET / 404 [0.06, 127.0.0.1:47602]
ERROR 2025-02-17 10:32:11,211 log Internal Server Error: /users/
Traceback (most recent call last):
  File "C:\Users\User\Desktop\docs\.venv\Lib\site-packages\asgiref\sync.py", line 518, in thread_handler
    raise exc_info[1]
  File "C:\Users\User\Desktop\docs\.venv\Lib\site-packages\django\core\handlers\exception.py", line 42, in inner
    response = await get_response(request)
               ^^^^^^^^^^^^^^^^^^^^^^^^^^^
  File "C:\Users\User\Desktop\docs\.venv\Lib\site-packages\asgiref\sync.py", line 518, in thread_handler
    raise exc_info[1]
  File "C:\Users\User\Desktop\docs\.venv\Lib\site-packages\django\core\handlers\base.py", line 253, in _get_response_async
    response = await wrapped_callback(
               ^^^^^^^^^^^^^^^^^^^^^^^
        request, *callback_args, **callback_kwargs
        ^^^^^^^^^^^^^^^^^^^^^^^^^^^^^^^^^^^^^^^^^^
    )
    ^
  File "C:\Users\User\Desktop\docs\.venv\Lib\site-packages\asgiref\sync.py", line 468, in __call__
    ret = await asyncio.shield(exec_coro)
          ^^^^^^^^^^^^^^^^^^^^^^^^^^^^^^^
  File "C:\Users\User\AppData\Local\Programs\Python\Python313\Lib\concurrent\futures\thread.py", line 59, in run
    result = self.fn(*self.args, **self.kwargs)
  File "C:\Users\User\Desktop\docs\.venv\Lib\site-packages\asgiref\sync.py", line 522, in thread_handler
    return func(*args, **kwargs)
  File "C:\Users\User\Desktop\docs\taskmanager\users\views.py", line 23, in index
    return render(request,'users/team_view.html',context={'users':users, 'departments':departments, 'tasks':tasks})
  File "C:\Users\User\Desktop\docs\.venv\Lib\site-packages\django\shortcuts.py", line 25, in render
    content = loader.render_to_string(template_name, context, request, using=using)
  File "C:\Users\User\Desktop\docs\.venv\Lib\site-packages\django\template\loader.py", line 61, in render_to_string
    template = get_template(template_name, using=using)
  File "C:\Users\User\Desktop\docs\.venv\Lib\site-packages\django\template\loader.py", line 19, in get_template
    raise TemplateDoesNotExist(template_name, chain=chain)
django.template.exceptions.TemplateDoesNotExist: users/team_view.html
ERROR 2025-02-17 10:32:11,231 runserver HTTP GET /users/ 500 [0.31, 127.0.0.1:47602]
ERROR 2025-02-17 10:32:18,804 log Internal Server Error: /users/
Traceback (most recent call last):
  File "C:\Users\User\Desktop\docs\.venv\Lib\site-packages\asgiref\sync.py", line 518, in thread_handler
    raise exc_info[1]
  File "C:\Users\User\Desktop\docs\.venv\Lib\site-packages\django\core\handlers\exception.py", line 42, in inner
    response = await get_response(request)
               ^^^^^^^^^^^^^^^^^^^^^^^^^^^
  File "C:\Users\User\Desktop\docs\.venv\Lib\site-packages\asgiref\sync.py", line 518, in thread_handler
    raise exc_info[1]
  File "C:\Users\User\Desktop\docs\.venv\Lib\site-packages\django\core\handlers\base.py", line 253, in _get_response_async
    response = await wrapped_callback(
               ^^^^^^^^^^^^^^^^^^^^^^^
        request, *callback_args, **callback_kwargs
        ^^^^^^^^^^^^^^^^^^^^^^^^^^^^^^^^^^^^^^^^^^
    )
    ^
  File "C:\Users\User\Desktop\docs\.venv\Lib\site-packages\asgiref\sync.py", line 468, in __call__
    ret = await asyncio.shield(exec_coro)
          ^^^^^^^^^^^^^^^^^^^^^^^^^^^^^^^
  File "C:\Users\User\AppData\Local\Programs\Python\Python313\Lib\concurrent\futures\thread.py", line 59, in run
    result = self.fn(*self.args, **self.kwargs)
  File "C:\Users\User\Desktop\docs\.venv\Lib\site-packages\asgiref\sync.py", line 522, in thread_handler
    return func(*args, **kwargs)
  File "C:\Users\User\Desktop\docs\taskmanager\users\views.py", line 23, in index
    return render(request,'users/team_view.html',context={'users':users, 'departments':departments, 'tasks':tasks})
  File "C:\Users\User\Desktop\docs\.venv\Lib\site-packages\django\shortcuts.py", line 25, in render
    content = loader.render_to_string(template_name, context, request, using=using)
  File "C:\Users\User\Desktop\docs\.venv\Lib\site-packages\django\template\loader.py", line 61, in render_to_string
    template = get_template(template_name, using=using)
  File "C:\Users\User\Desktop\docs\.venv\Lib\site-packages\django\template\loader.py", line 19, in get_template
    raise TemplateDoesNotExist(template_name, chain=chain)
django.template.exceptions.TemplateDoesNotExist: users/team_view.html
ERROR 2025-02-17 10:32:18,807 runserver HTTP GET /users/ 500 [0.03, 127.0.0.1:47602]
ERROR 2025-02-17 10:32:32,989 log Internal Server Error: /users/
Traceback (most recent call last):
  File "C:\Users\User\Desktop\docs\.venv\Lib\site-packages\asgiref\sync.py", line 518, in thread_handler
    raise exc_info[1]
  File "C:\Users\User\Desktop\docs\.venv\Lib\site-packages\django\core\handlers\exception.py", line 42, in inner
    response = await get_response(request)
               ^^^^^^^^^^^^^^^^^^^^^^^^^^^
  File "C:\Users\User\Desktop\docs\.venv\Lib\site-packages\asgiref\sync.py", line 518, in thread_handler
    raise exc_info[1]
  File "C:\Users\User\Desktop\docs\.venv\Lib\site-packages\django\core\handlers\base.py", line 253, in _get_response_async
    response = await wrapped_callback(
               ^^^^^^^^^^^^^^^^^^^^^^^
        request, *callback_args, **callback_kwargs
        ^^^^^^^^^^^^^^^^^^^^^^^^^^^^^^^^^^^^^^^^^^
    )
    ^
  File "C:\Users\User\Desktop\docs\.venv\Lib\site-packages\asgiref\sync.py", line 468, in __call__
    ret = await asyncio.shield(exec_coro)
          ^^^^^^^^^^^^^^^^^^^^^^^^^^^^^^^
  File "C:\Users\User\AppData\Local\Programs\Python\Python313\Lib\concurrent\futures\thread.py", line 59, in run
    result = self.fn(*self.args, **self.kwargs)
  File "C:\Users\User\Desktop\docs\.venv\Lib\site-packages\asgiref\sync.py", line 522, in thread_handler
    return func(*args, **kwargs)
  File "C:\Users\User\Desktop\docs\taskmanager\users\views.py", line 23, in index
    return render(request,'users/team-view.html',context={'users':users, 'departments':departments, 'tasks':tasks})
  File "C:\Users\User\Desktop\docs\.venv\Lib\site-packages\django\shortcuts.py", line 25, in render
    content = loader.render_to_string(template_name, context, request, using=using)
  File "C:\Users\User\Desktop\docs\.venv\Lib\site-packages\django\template\loader.py", line 61, in render_to_string
    template = get_template(template_name, using=using)
  File "C:\Users\User\Desktop\docs\.venv\Lib\site-packages\django\template\loader.py", line 19, in get_template
    raise TemplateDoesNotExist(template_name, chain=chain)
django.template.exceptions.TemplateDoesNotExist: users/team-view.html
ERROR 2025-02-17 10:32:32,993 runserver HTTP GET /users/ 500 [0.22, 127.0.0.1:47614]
ERROR 2025-02-17 10:32:33,889 log Internal Server Error: /users/
Traceback (most recent call last):
  File "C:\Users\User\Desktop\docs\.venv\Lib\site-packages\asgiref\sync.py", line 518, in thread_handler
    raise exc_info[1]
  File "C:\Users\User\Desktop\docs\.venv\Lib\site-packages\django\core\handlers\exception.py", line 42, in inner
    response = await get_response(request)
               ^^^^^^^^^^^^^^^^^^^^^^^^^^^
  File "C:\Users\User\Desktop\docs\.venv\Lib\site-packages\asgiref\sync.py", line 518, in thread_handler
    raise exc_info[1]
  File "C:\Users\User\Desktop\docs\.venv\Lib\site-packages\django\core\handlers\base.py", line 253, in _get_response_async
    response = await wrapped_callback(
               ^^^^^^^^^^^^^^^^^^^^^^^
        request, *callback_args, **callback_kwargs
        ^^^^^^^^^^^^^^^^^^^^^^^^^^^^^^^^^^^^^^^^^^
    )
    ^
  File "C:\Users\User\Desktop\docs\.venv\Lib\site-packages\asgiref\sync.py", line 468, in __call__
    ret = await asyncio.shield(exec_coro)
          ^^^^^^^^^^^^^^^^^^^^^^^^^^^^^^^
  File "C:\Users\User\AppData\Local\Programs\Python\Python313\Lib\concurrent\futures\thread.py", line 59, in run
    result = self.fn(*self.args, **self.kwargs)
  File "C:\Users\User\Desktop\docs\.venv\Lib\site-packages\asgiref\sync.py", line 522, in thread_handler
    return func(*args, **kwargs)
  File "C:\Users\User\Desktop\docs\taskmanager\users\views.py", line 23, in index
    return render(request,'users/team-view.html',context={'users':users, 'departments':departments, 'tasks':tasks})
  File "C:\Users\User\Desktop\docs\.venv\Lib\site-packages\django\shortcuts.py", line 25, in render
    content = loader.render_to_string(template_name, context, request, using=using)
  File "C:\Users\User\Desktop\docs\.venv\Lib\site-packages\django\template\loader.py", line 61, in render_to_string
    template = get_template(template_name, using=using)
  File "C:\Users\User\Desktop\docs\.venv\Lib\site-packages\django\template\loader.py", line 19, in get_template
    raise TemplateDoesNotExist(template_name, chain=chain)
django.template.exceptions.TemplateDoesNotExist: users/team-view.html
ERROR 2025-02-17 10:32:33,895 runserver HTTP GET /users/ 500 [0.04, 127.0.0.1:47614]
ERROR 2025-02-17 10:33:30,058 log Internal Server Error: /users/
Traceback (most recent call last):
  File "C:\Users\User\Desktop\docs\.venv\Lib\site-packages\asgiref\sync.py", line 518, in thread_handler
    raise exc_info[1]
  File "C:\Users\User\Desktop\docs\.venv\Lib\site-packages\django\core\handlers\exception.py", line 42, in inner
    response = await get_response(request)
               ^^^^^^^^^^^^^^^^^^^^^^^^^^^
  File "C:\Users\User\Desktop\docs\.venv\Lib\site-packages\asgiref\sync.py", line 518, in thread_handler
    raise exc_info[1]
  File "C:\Users\User\Desktop\docs\.venv\Lib\site-packages\django\core\handlers\base.py", line 253, in _get_response_async
    response = await wrapped_callback(
               ^^^^^^^^^^^^^^^^^^^^^^^
        request, *callback_args, **callback_kwargs
        ^^^^^^^^^^^^^^^^^^^^^^^^^^^^^^^^^^^^^^^^^^
    )
    ^
  File "C:\Users\User\Desktop\docs\.venv\Lib\site-packages\asgiref\sync.py", line 468, in __call__
    ret = await asyncio.shield(exec_coro)
          ^^^^^^^^^^^^^^^^^^^^^^^^^^^^^^^
  File "C:\Users\User\AppData\Local\Programs\Python\Python313\Lib\concurrent\futures\thread.py", line 59, in run
    result = self.fn(*self.args, **self.kwargs)
  File "C:\Users\User\Desktop\docs\.venv\Lib\site-packages\asgiref\sync.py", line 522, in thread_handler
    return func(*args, **kwargs)
  File "C:\Users\User\Desktop\docs\taskmanager\users\views.py", line 23, in index
    return render(request,'users/team-view.html',context={'users':users, 'departments':departments, 'tasks':tasks})
  File "C:\Users\User\Desktop\docs\.venv\Lib\site-packages\django\shortcuts.py", line 25, in render
    content = loader.render_to_string(template_name, context, request, using=using)
  File "C:\Users\User\Desktop\docs\.venv\Lib\site-packages\django\template\loader.py", line 61, in render_to_string
    template = get_template(template_name, using=using)
  File "C:\Users\User\Desktop\docs\.venv\Lib\site-packages\django\template\loader.py", line 19, in get_template
    raise TemplateDoesNotExist(template_name, chain=chain)
django.template.exceptions.TemplateDoesNotExist: users/team-view.html
ERROR 2025-02-17 10:33:30,062 runserver HTTP GET /users/ 500 [0.04, 127.0.0.1:47614]
ERROR 2025-02-17 10:34:09,682 log Internal Server Error: /users/
Traceback (most recent call last):
  File "C:\Users\User\Desktop\docs\.venv\Lib\site-packages\asgiref\sync.py", line 518, in thread_handler
    raise exc_info[1]
  File "C:\Users\User\Desktop\docs\.venv\Lib\site-packages\django\core\handlers\exception.py", line 42, in inner
    response = await get_response(request)
               ^^^^^^^^^^^^^^^^^^^^^^^^^^^
  File "C:\Users\User\Desktop\docs\.venv\Lib\site-packages\asgiref\sync.py", line 518, in thread_handler
    raise exc_info[1]
  File "C:\Users\User\Desktop\docs\.venv\Lib\site-packages\django\core\handlers\base.py", line 253, in _get_response_async
    response = await wrapped_callback(
               ^^^^^^^^^^^^^^^^^^^^^^^
        request, *callback_args, **callback_kwargs
        ^^^^^^^^^^^^^^^^^^^^^^^^^^^^^^^^^^^^^^^^^^
    )
    ^
  File "C:\Users\User\Desktop\docs\.venv\Lib\site-packages\asgiref\sync.py", line 468, in __call__
    ret = await asyncio.shield(exec_coro)
          ^^^^^^^^^^^^^^^^^^^^^^^^^^^^^^^
  File "C:\Users\User\AppData\Local\Programs\Python\Python313\Lib\concurrent\futures\thread.py", line 59, in run
    result = self.fn(*self.args, **self.kwargs)
  File "C:\Users\User\Desktop\docs\.venv\Lib\site-packages\asgiref\sync.py", line 522, in thread_handler
    return func(*args, **kwargs)
  File "C:\Users\User\Desktop\docs\taskmanager\users\views.py", line 23, in index
    return render(request,'users/team-view.html',context={'users':users, 'departments':departments, 'tasks':tasks})
  File "C:\Users\User\Desktop\docs\.venv\Lib\site-packages\django\shortcuts.py", line 25, in render
    content = loader.render_to_string(template_name, context, request, using=using)
  File "C:\Users\User\Desktop\docs\.venv\Lib\site-packages\django\template\loader.py", line 61, in render_to_string
    template = get_template(template_name, using=using)
  File "C:\Users\User\Desktop\docs\.venv\Lib\site-packages\django\template\loader.py", line 19, in get_template
    raise TemplateDoesNotExist(template_name, chain=chain)
django.template.exceptions.TemplateDoesNotExist: users/team-view.html
ERROR 2025-02-17 10:34:09,686 runserver HTTP GET /users/ 500 [0.03, 127.0.0.1:47614]
WARNING 2025-02-17 10:34:12,505 log Not Found: /
WARNING 2025-02-17 10:34:12,506 runserver HTTP GET / 404 [0.01, 127.0.0.1:47614]
ERROR 2025-02-17 10:34:16,476 log Internal Server Error: /users/
Traceback (most recent call last):
  File "C:\Users\User\Desktop\docs\.venv\Lib\site-packages\asgiref\sync.py", line 518, in thread_handler
    raise exc_info[1]
  File "C:\Users\User\Desktop\docs\.venv\Lib\site-packages\django\core\handlers\exception.py", line 42, in inner
    response = await get_response(request)
               ^^^^^^^^^^^^^^^^^^^^^^^^^^^
  File "C:\Users\User\Desktop\docs\.venv\Lib\site-packages\asgiref\sync.py", line 518, in thread_handler
    raise exc_info[1]
  File "C:\Users\User\Desktop\docs\.venv\Lib\site-packages\django\core\handlers\base.py", line 253, in _get_response_async
    response = await wrapped_callback(
               ^^^^^^^^^^^^^^^^^^^^^^^
        request, *callback_args, **callback_kwargs
        ^^^^^^^^^^^^^^^^^^^^^^^^^^^^^^^^^^^^^^^^^^
    )
    ^
  File "C:\Users\User\Desktop\docs\.venv\Lib\site-packages\asgiref\sync.py", line 468, in __call__
    ret = await asyncio.shield(exec_coro)
          ^^^^^^^^^^^^^^^^^^^^^^^^^^^^^^^
  File "C:\Users\User\AppData\Local\Programs\Python\Python313\Lib\concurrent\futures\thread.py", line 59, in run
    result = self.fn(*self.args, **self.kwargs)
  File "C:\Users\User\Desktop\docs\.venv\Lib\site-packages\asgiref\sync.py", line 522, in thread_handler
    return func(*args, **kwargs)
  File "C:\Users\User\Desktop\docs\taskmanager\users\views.py", line 23, in index
    return render(request,'users/team-view.html',context={'users':users, 'departments':departments, 'tasks':tasks})
  File "C:\Users\User\Desktop\docs\.venv\Lib\site-packages\django\shortcuts.py", line 25, in render
    content = loader.render_to_string(template_name, context, request, using=using)
  File "C:\Users\User\Desktop\docs\.venv\Lib\site-packages\django\template\loader.py", line 61, in render_to_string
    template = get_template(template_name, using=using)
  File "C:\Users\User\Desktop\docs\.venv\Lib\site-packages\django\template\loader.py", line 19, in get_template
    raise TemplateDoesNotExist(template_name, chain=chain)
django.template.exceptions.TemplateDoesNotExist: users/team-view.html
ERROR 2025-02-17 10:34:16,480 runserver HTTP GET /users/ 500 [0.03, 127.0.0.1:47614]
ERROR 2025-02-17 10:34:25,786 log Internal Server Error: /users/
Traceback (most recent call last):
  File "C:\Users\User\Desktop\docs\.venv\Lib\site-packages\asgiref\sync.py", line 518, in thread_handler
    raise exc_info[1]
  File "C:\Users\User\Desktop\docs\.venv\Lib\site-packages\django\core\handlers\exception.py", line 42, in inner
    response = await get_response(request)
               ^^^^^^^^^^^^^^^^^^^^^^^^^^^
  File "C:\Users\User\Desktop\docs\.venv\Lib\site-packages\asgiref\sync.py", line 518, in thread_handler
    raise exc_info[1]
  File "C:\Users\User\Desktop\docs\.venv\Lib\site-packages\django\core\handlers\base.py", line 253, in _get_response_async
    response = await wrapped_callback(
               ^^^^^^^^^^^^^^^^^^^^^^^
        request, *callback_args, **callback_kwargs
        ^^^^^^^^^^^^^^^^^^^^^^^^^^^^^^^^^^^^^^^^^^
    )
    ^
  File "C:\Users\User\Desktop\docs\.venv\Lib\site-packages\asgiref\sync.py", line 468, in __call__
    ret = await asyncio.shield(exec_coro)
          ^^^^^^^^^^^^^^^^^^^^^^^^^^^^^^^
  File "C:\Users\User\AppData\Local\Programs\Python\Python313\Lib\concurrent\futures\thread.py", line 59, in run
    result = self.fn(*self.args, **self.kwargs)
  File "C:\Users\User\Desktop\docs\.venv\Lib\site-packages\asgiref\sync.py", line 522, in thread_handler
    return func(*args, **kwargs)
  File "C:\Users\User\Desktop\docs\taskmanager\users\views.py", line 23, in index
    return render(request,'users/team_view.html',context={'users':users, 'departments':departments, 'tasks':tasks})
  File "C:\Users\User\Desktop\docs\.venv\Lib\site-packages\django\shortcuts.py", line 25, in render
    content = loader.render_to_string(template_name, context, request, using=using)
  File "C:\Users\User\Desktop\docs\.venv\Lib\site-packages\django\template\loader.py", line 61, in render_to_string
    template = get_template(template_name, using=using)
  File "C:\Users\User\Desktop\docs\.venv\Lib\site-packages\django\template\loader.py", line 19, in get_template
    raise TemplateDoesNotExist(template_name, chain=chain)
django.template.exceptions.TemplateDoesNotExist: users/team_view.html
ERROR 2025-02-17 10:34:25,791 runserver HTTP GET /users/ 500 [0.10, 127.0.0.1:47623]
ERROR 2025-02-17 10:35:01,403 log Internal Server Error: /users/
Traceback (most recent call last):
  File "C:\Users\User\Desktop\docs\.venv\Lib\site-packages\asgiref\sync.py", line 518, in thread_handler
    raise exc_info[1]
  File "C:\Users\User\Desktop\docs\.venv\Lib\site-packages\django\core\handlers\exception.py", line 42, in inner
    response = await get_response(request)
               ^^^^^^^^^^^^^^^^^^^^^^^^^^^
  File "C:\Users\User\Desktop\docs\.venv\Lib\site-packages\asgiref\sync.py", line 518, in thread_handler
    raise exc_info[1]
  File "C:\Users\User\Desktop\docs\.venv\Lib\site-packages\django\core\handlers\base.py", line 253, in _get_response_async
    response = await wrapped_callback(
               ^^^^^^^^^^^^^^^^^^^^^^^
        request, *callback_args, **callback_kwargs
        ^^^^^^^^^^^^^^^^^^^^^^^^^^^^^^^^^^^^^^^^^^
    )
    ^
  File "C:\Users\User\Desktop\docs\.venv\Lib\site-packages\asgiref\sync.py", line 468, in __call__
    ret = await asyncio.shield(exec_coro)
          ^^^^^^^^^^^^^^^^^^^^^^^^^^^^^^^
  File "C:\Users\User\AppData\Local\Programs\Python\Python313\Lib\concurrent\futures\thread.py", line 59, in run
    result = self.fn(*self.args, **self.kwargs)
  File "C:\Users\User\Desktop\docs\.venv\Lib\site-packages\asgiref\sync.py", line 522, in thread_handler
    return func(*args, **kwargs)
  File "C:\Users\User\Desktop\docs\taskmanager\users\views.py", line 23, in index
    return render(request,'users/team_view.html',context={'users':users, 'departments':departments, 'tasks':tasks})
  File "C:\Users\User\Desktop\docs\.venv\Lib\site-packages\django\shortcuts.py", line 25, in render
    content = loader.render_to_string(template_name, context, request, using=using)
  File "C:\Users\User\Desktop\docs\.venv\Lib\site-packages\django\template\loader.py", line 61, in render_to_string
    template = get_template(template_name, using=using)
  File "C:\Users\User\Desktop\docs\.venv\Lib\site-packages\django\template\loader.py", line 19, in get_template
    raise TemplateDoesNotExist(template_name, chain=chain)
django.template.exceptions.TemplateDoesNotExist: users/team_view.html
ERROR 2025-02-17 10:35:01,407 runserver HTTP GET /users/ 500 [0.10, 127.0.0.1:47645]
ERROR 2025-02-17 10:35:29,234 log Internal Server Error: /users/
Traceback (most recent call last):
  File "C:\Users\User\Desktop\docs\.venv\Lib\site-packages\asgiref\sync.py", line 518, in thread_handler
    raise exc_info[1]
  File "C:\Users\User\Desktop\docs\.venv\Lib\site-packages\django\core\handlers\exception.py", line 42, in inner
    response = await get_response(request)
               ^^^^^^^^^^^^^^^^^^^^^^^^^^^
  File "C:\Users\User\Desktop\docs\.venv\Lib\site-packages\asgiref\sync.py", line 518, in thread_handler
    raise exc_info[1]
  File "C:\Users\User\Desktop\docs\.venv\Lib\site-packages\django\core\handlers\base.py", line 253, in _get_response_async
    response = await wrapped_callback(
               ^^^^^^^^^^^^^^^^^^^^^^^
        request, *callback_args, **callback_kwargs
        ^^^^^^^^^^^^^^^^^^^^^^^^^^^^^^^^^^^^^^^^^^
    )
    ^
  File "C:\Users\User\Desktop\docs\.venv\Lib\site-packages\asgiref\sync.py", line 468, in __call__
    ret = await asyncio.shield(exec_coro)
          ^^^^^^^^^^^^^^^^^^^^^^^^^^^^^^^
  File "C:\Users\User\AppData\Local\Programs\Python\Python313\Lib\concurrent\futures\thread.py", line 59, in run
    result = self.fn(*self.args, **self.kwargs)
  File "C:\Users\User\Desktop\docs\.venv\Lib\site-packages\asgiref\sync.py", line 522, in thread_handler
    return func(*args, **kwargs)
  File "C:\Users\User\Desktop\docs\taskmanager\users\views.py", line 23, in index
    return render(request,'team_view.html',context={'users':users, 'departments':departments, 'tasks':tasks})
  File "C:\Users\User\Desktop\docs\.venv\Lib\site-packages\django\shortcuts.py", line 25, in render
    content = loader.render_to_string(template_name, context, request, using=using)
  File "C:\Users\User\Desktop\docs\.venv\Lib\site-packages\django\template\loader.py", line 61, in render_to_string
    template = get_template(template_name, using=using)
  File "C:\Users\User\Desktop\docs\.venv\Lib\site-packages\django\template\loader.py", line 19, in get_template
    raise TemplateDoesNotExist(template_name, chain=chain)
django.template.exceptions.TemplateDoesNotExist: team_view.html
ERROR 2025-02-17 10:35:29,238 runserver HTTP GET /users/ 500 [0.25, 127.0.0.1:47654]
ERROR 2025-02-17 10:35:39,636 log Internal Server Error: /users/
Traceback (most recent call last):
  File "C:\Users\User\Desktop\docs\.venv\Lib\site-packages\asgiref\sync.py", line 518, in thread_handler
    raise exc_info[1]
  File "C:\Users\User\Desktop\docs\.venv\Lib\site-packages\django\core\handlers\exception.py", line 42, in inner
    response = await get_response(request)
               ^^^^^^^^^^^^^^^^^^^^^^^^^^^
  File "C:\Users\User\Desktop\docs\.venv\Lib\site-packages\asgiref\sync.py", line 518, in thread_handler
    raise exc_info[1]
  File "C:\Users\User\Desktop\docs\.venv\Lib\site-packages\django\core\handlers\base.py", line 253, in _get_response_async
    response = await wrapped_callback(
               ^^^^^^^^^^^^^^^^^^^^^^^
        request, *callback_args, **callback_kwargs
        ^^^^^^^^^^^^^^^^^^^^^^^^^^^^^^^^^^^^^^^^^^
    )
    ^
  File "C:\Users\User\Desktop\docs\.venv\Lib\site-packages\asgiref\sync.py", line 468, in __call__
    ret = await asyncio.shield(exec_coro)
          ^^^^^^^^^^^^^^^^^^^^^^^^^^^^^^^
  File "C:\Users\User\AppData\Local\Programs\Python\Python313\Lib\concurrent\futures\thread.py", line 59, in run
    result = self.fn(*self.args, **self.kwargs)
  File "C:\Users\User\Desktop\docs\.venv\Lib\site-packages\asgiref\sync.py", line 522, in thread_handler
    return func(*args, **kwargs)
  File "C:\Users\User\Desktop\docs\taskmanager\users\views.py", line 23, in index
    return render(request,'templates/users/team_view.html',context={'users':users, 'departments':departments, 'tasks':tasks})
  File "C:\Users\User\Desktop\docs\.venv\Lib\site-packages\django\shortcuts.py", line 25, in render
    content = loader.render_to_string(template_name, context, request, using=using)
  File "C:\Users\User\Desktop\docs\.venv\Lib\site-packages\django\template\loader.py", line 61, in render_to_string
    template = get_template(template_name, using=using)
  File "C:\Users\User\Desktop\docs\.venv\Lib\site-packages\django\template\loader.py", line 19, in get_template
    raise TemplateDoesNotExist(template_name, chain=chain)
django.template.exceptions.TemplateDoesNotExist: templates/users/team_view.html
ERROR 2025-02-17 10:35:39,641 runserver HTTP GET /users/ 500 [0.23, 127.0.0.1:47661]
ERROR 2025-02-17 10:38:03,868 log Internal Server Error: /users/
Traceback (most recent call last):
  File "C:\Users\User\Desktop\docs\.venv\Lib\site-packages\asgiref\sync.py", line 518, in thread_handler
    raise exc_info[1]
  File "C:\Users\User\Desktop\docs\.venv\Lib\site-packages\django\core\handlers\exception.py", line 42, in inner
    response = await get_response(request)
               ^^^^^^^^^^^^^^^^^^^^^^^^^^^
  File "C:\Users\User\Desktop\docs\.venv\Lib\site-packages\asgiref\sync.py", line 518, in thread_handler
    raise exc_info[1]
  File "C:\Users\User\Desktop\docs\.venv\Lib\site-packages\django\core\handlers\base.py", line 253, in _get_response_async
    response = await wrapped_callback(
               ^^^^^^^^^^^^^^^^^^^^^^^
        request, *callback_args, **callback_kwargs
        ^^^^^^^^^^^^^^^^^^^^^^^^^^^^^^^^^^^^^^^^^^
    )
    ^
  File "C:\Users\User\Desktop\docs\.venv\Lib\site-packages\asgiref\sync.py", line 468, in __call__
    ret = await asyncio.shield(exec_coro)
          ^^^^^^^^^^^^^^^^^^^^^^^^^^^^^^^
  File "C:\Users\User\AppData\Local\Programs\Python\Python313\Lib\concurrent\futures\thread.py", line 59, in run
    result = self.fn(*self.args, **self.kwargs)
  File "C:\Users\User\Desktop\docs\.venv\Lib\site-packages\asgiref\sync.py", line 522, in thread_handler
    return func(*args, **kwargs)
  File "C:\Users\User\Desktop\docs\taskmanager\users\views.py", line 23, in index
    return render(request,'users/team_view.html',context={'users':users, 'departments':departments, 'tasks':tasks})
  File "C:\Users\User\Desktop\docs\.venv\Lib\site-packages\django\shortcuts.py", line 25, in render
    content = loader.render_to_string(template_name, context, request, using=using)
  File "C:\Users\User\Desktop\docs\.venv\Lib\site-packages\django\template\loader.py", line 61, in render_to_string
    template = get_template(template_name, using=using)
  File "C:\Users\User\Desktop\docs\.venv\Lib\site-packages\django\template\loader.py", line 19, in get_template
    raise TemplateDoesNotExist(template_name, chain=chain)
django.template.exceptions.TemplateDoesNotExist: users/team_view.html
ERROR 2025-02-17 10:38:03,872 runserver HTTP GET /users/ 500 [0.11, 127.0.0.1:47711]
ERROR 2025-02-17 10:38:35,650 log Internal Server Error: /users/
Traceback (most recent call last):
  File "C:\Users\User\Desktop\docs\.venv\Lib\site-packages\asgiref\sync.py", line 518, in thread_handler
    raise exc_info[1]
  File "C:\Users\User\Desktop\docs\.venv\Lib\site-packages\django\core\handlers\exception.py", line 42, in inner
    response = await get_response(request)
               ^^^^^^^^^^^^^^^^^^^^^^^^^^^
  File "C:\Users\User\Desktop\docs\.venv\Lib\site-packages\asgiref\sync.py", line 518, in thread_handler
    raise exc_info[1]
  File "C:\Users\User\Desktop\docs\.venv\Lib\site-packages\django\core\handlers\base.py", line 253, in _get_response_async
    response = await wrapped_callback(
               ^^^^^^^^^^^^^^^^^^^^^^^
        request, *callback_args, **callback_kwargs
        ^^^^^^^^^^^^^^^^^^^^^^^^^^^^^^^^^^^^^^^^^^
    )
    ^
  File "C:\Users\User\Desktop\docs\.venv\Lib\site-packages\asgiref\sync.py", line 468, in __call__
    ret = await asyncio.shield(exec_coro)
          ^^^^^^^^^^^^^^^^^^^^^^^^^^^^^^^
  File "C:\Users\User\AppData\Local\Programs\Python\Python313\Lib\concurrent\futures\thread.py", line 59, in run
    result = self.fn(*self.args, **self.kwargs)
  File "C:\Users\User\Desktop\docs\.venv\Lib\site-packages\asgiref\sync.py", line 522, in thread_handler
    return func(*args, **kwargs)
  File "C:\Users\User\Desktop\docs\taskmanager\users\views.py", line 23, in index
    return render(request,'base.html',context={'users':users, 'departments':departments, 'tasks':tasks})
  File "C:\Users\User\Desktop\docs\.venv\Lib\site-packages\django\shortcuts.py", line 25, in render
    content = loader.render_to_string(template_name, context, request, using=using)
  File "C:\Users\User\Desktop\docs\.venv\Lib\site-packages\django\template\loader.py", line 61, in render_to_string
    template = get_template(template_name, using=using)
  File "C:\Users\User\Desktop\docs\.venv\Lib\site-packages\django\template\loader.py", line 19, in get_template
    raise TemplateDoesNotExist(template_name, chain=chain)
django.template.exceptions.TemplateDoesNotExist: base.html
ERROR 2025-02-17 10:38:35,654 runserver HTTP GET /users/ 500 [0.09, 127.0.0.1:47722]
ERROR 2025-02-17 10:38:35,969 log Internal Server Error: /users/
Traceback (most recent call last):
  File "C:\Users\User\Desktop\docs\.venv\Lib\site-packages\asgiref\sync.py", line 518, in thread_handler
    raise exc_info[1]
  File "C:\Users\User\Desktop\docs\.venv\Lib\site-packages\django\core\handlers\exception.py", line 42, in inner
    response = await get_response(request)
               ^^^^^^^^^^^^^^^^^^^^^^^^^^^
  File "C:\Users\User\Desktop\docs\.venv\Lib\site-packages\asgiref\sync.py", line 518, in thread_handler
    raise exc_info[1]
  File "C:\Users\User\Desktop\docs\.venv\Lib\site-packages\django\core\handlers\base.py", line 253, in _get_response_async
    response = await wrapped_callback(
               ^^^^^^^^^^^^^^^^^^^^^^^
        request, *callback_args, **callback_kwargs
        ^^^^^^^^^^^^^^^^^^^^^^^^^^^^^^^^^^^^^^^^^^
    )
    ^
  File "C:\Users\User\Desktop\docs\.venv\Lib\site-packages\asgiref\sync.py", line 468, in __call__
    ret = await asyncio.shield(exec_coro)
          ^^^^^^^^^^^^^^^^^^^^^^^^^^^^^^^
  File "C:\Users\User\AppData\Local\Programs\Python\Python313\Lib\concurrent\futures\thread.py", line 59, in run
    result = self.fn(*self.args, **self.kwargs)
  File "C:\Users\User\Desktop\docs\.venv\Lib\site-packages\asgiref\sync.py", line 522, in thread_handler
    return func(*args, **kwargs)
  File "C:\Users\User\Desktop\docs\taskmanager\users\views.py", line 23, in index
    return render(request,'base.html',context={'users':users, 'departments':departments, 'tasks':tasks})
  File "C:\Users\User\Desktop\docs\.venv\Lib\site-packages\django\shortcuts.py", line 25, in render
    content = loader.render_to_string(template_name, context, request, using=using)
  File "C:\Users\User\Desktop\docs\.venv\Lib\site-packages\django\template\loader.py", line 61, in render_to_string
    template = get_template(template_name, using=using)
  File "C:\Users\User\Desktop\docs\.venv\Lib\site-packages\django\template\loader.py", line 19, in get_template
    raise TemplateDoesNotExist(template_name, chain=chain)
django.template.exceptions.TemplateDoesNotExist: base.html
ERROR 2025-02-17 10:38:35,972 runserver HTTP GET /users/ 500 [0.03, 127.0.0.1:47722]
ERROR 2025-02-17 10:38:36,301 log Internal Server Error: /users/
Traceback (most recent call last):
  File "C:\Users\User\Desktop\docs\.venv\Lib\site-packages\asgiref\sync.py", line 518, in thread_handler
    raise exc_info[1]
  File "C:\Users\User\Desktop\docs\.venv\Lib\site-packages\django\core\handlers\exception.py", line 42, in inner
    response = await get_response(request)
               ^^^^^^^^^^^^^^^^^^^^^^^^^^^
  File "C:\Users\User\Desktop\docs\.venv\Lib\site-packages\asgiref\sync.py", line 518, in thread_handler
    raise exc_info[1]
  File "C:\Users\User\Desktop\docs\.venv\Lib\site-packages\django\core\handlers\base.py", line 253, in _get_response_async
    response = await wrapped_callback(
               ^^^^^^^^^^^^^^^^^^^^^^^
        request, *callback_args, **callback_kwargs
        ^^^^^^^^^^^^^^^^^^^^^^^^^^^^^^^^^^^^^^^^^^
    )
    ^
  File "C:\Users\User\Desktop\docs\.venv\Lib\site-packages\asgiref\sync.py", line 468, in __call__
    ret = await asyncio.shield(exec_coro)
          ^^^^^^^^^^^^^^^^^^^^^^^^^^^^^^^
  File "C:\Users\User\AppData\Local\Programs\Python\Python313\Lib\concurrent\futures\thread.py", line 59, in run
    result = self.fn(*self.args, **self.kwargs)
  File "C:\Users\User\Desktop\docs\.venv\Lib\site-packages\asgiref\sync.py", line 522, in thread_handler
    return func(*args, **kwargs)
  File "C:\Users\User\Desktop\docs\taskmanager\users\views.py", line 23, in index
    return render(request,'base.html',context={'users':users, 'departments':departments, 'tasks':tasks})
  File "C:\Users\User\Desktop\docs\.venv\Lib\site-packages\django\shortcuts.py", line 25, in render
    content = loader.render_to_string(template_name, context, request, using=using)
  File "C:\Users\User\Desktop\docs\.venv\Lib\site-packages\django\template\loader.py", line 61, in render_to_string
    template = get_template(template_name, using=using)
  File "C:\Users\User\Desktop\docs\.venv\Lib\site-packages\django\template\loader.py", line 19, in get_template
    raise TemplateDoesNotExist(template_name, chain=chain)
django.template.exceptions.TemplateDoesNotExist: base.html
ERROR 2025-02-17 10:38:36,305 runserver HTTP GET /users/ 500 [0.05, 127.0.0.1:47722]
WARNING 2025-02-17 10:40:05,368 log Not Found: /
WARNING 2025-02-17 10:40:05,369 runserver HTTP GET / 404 [0.01, 127.0.0.1:47746]
ERROR 2025-02-17 10:40:17,758 log Internal Server Error: /users/
Traceback (most recent call last):
  File "C:\Users\User\Desktop\docs\.venv\Lib\site-packages\asgiref\sync.py", line 518, in thread_handler
    raise exc_info[1]
  File "C:\Users\User\Desktop\docs\.venv\Lib\site-packages\django\core\handlers\exception.py", line 42, in inner
    response = await get_response(request)
               ^^^^^^^^^^^^^^^^^^^^^^^^^^^
  File "C:\Users\User\Desktop\docs\.venv\Lib\site-packages\asgiref\sync.py", line 518, in thread_handler
    raise exc_info[1]
  File "C:\Users\User\Desktop\docs\.venv\Lib\site-packages\django\core\handlers\base.py", line 253, in _get_response_async
    response = await wrapped_callback(
               ^^^^^^^^^^^^^^^^^^^^^^^
        request, *callback_args, **callback_kwargs
        ^^^^^^^^^^^^^^^^^^^^^^^^^^^^^^^^^^^^^^^^^^
    )
    ^
  File "C:\Users\User\Desktop\docs\.venv\Lib\site-packages\asgiref\sync.py", line 468, in __call__
    ret = await asyncio.shield(exec_coro)
          ^^^^^^^^^^^^^^^^^^^^^^^^^^^^^^^
  File "C:\Users\User\AppData\Local\Programs\Python\Python313\Lib\concurrent\futures\thread.py", line 59, in run
    result = self.fn(*self.args, **self.kwargs)
  File "C:\Users\User\Desktop\docs\.venv\Lib\site-packages\asgiref\sync.py", line 522, in thread_handler
    return func(*args, **kwargs)
  File "C:\Users\User\Desktop\docs\taskmanager\users\views.py", line 23, in index
    return render(request,'base.html',context={'users':users, 'departments':departments, 'tasks':tasks})
  File "C:\Users\User\Desktop\docs\.venv\Lib\site-packages\django\shortcuts.py", line 25, in render
    content = loader.render_to_string(template_name, context, request, using=using)
  File "C:\Users\User\Desktop\docs\.venv\Lib\site-packages\django\template\loader.py", line 61, in render_to_string
    template = get_template(template_name, using=using)
  File "C:\Users\User\Desktop\docs\.venv\Lib\site-packages\django\template\loader.py", line 19, in get_template
    raise TemplateDoesNotExist(template_name, chain=chain)
django.template.exceptions.TemplateDoesNotExist: base.html
ERROR 2025-02-17 10:40:17,762 runserver HTTP GET /users/ 500 [0.03, 127.0.0.1:47746]
ERROR 2025-02-17 10:40:53,609 log Internal Server Error: /users/
Traceback (most recent call last):
  File "C:\Users\User\Desktop\docs\.venv\Lib\site-packages\asgiref\sync.py", line 518, in thread_handler
    raise exc_info[1]
  File "C:\Users\User\Desktop\docs\.venv\Lib\site-packages\django\core\handlers\exception.py", line 42, in inner
    response = await get_response(request)
               ^^^^^^^^^^^^^^^^^^^^^^^^^^^
  File "C:\Users\User\Desktop\docs\.venv\Lib\site-packages\asgiref\sync.py", line 518, in thread_handler
    raise exc_info[1]
  File "C:\Users\User\Desktop\docs\.venv\Lib\site-packages\django\core\handlers\base.py", line 253, in _get_response_async
    response = await wrapped_callback(
               ^^^^^^^^^^^^^^^^^^^^^^^
        request, *callback_args, **callback_kwargs
        ^^^^^^^^^^^^^^^^^^^^^^^^^^^^^^^^^^^^^^^^^^
    )
    ^
  File "C:\Users\User\Desktop\docs\.venv\Lib\site-packages\asgiref\sync.py", line 468, in __call__
    ret = await asyncio.shield(exec_coro)
          ^^^^^^^^^^^^^^^^^^^^^^^^^^^^^^^
  File "C:\Users\User\AppData\Local\Programs\Python\Python313\Lib\concurrent\futures\thread.py", line 59, in run
    result = self.fn(*self.args, **self.kwargs)
  File "C:\Users\User\Desktop\docs\.venv\Lib\site-packages\asgiref\sync.py", line 522, in thread_handler
    return func(*args, **kwargs)
  File "C:\Users\User\Desktop\docs\taskmanager\users\views.py", line 23, in index
    return render(request,'templates/base.html',context={'users':users, 'departments':departments, 'tasks':tasks})
  File "C:\Users\User\Desktop\docs\.venv\Lib\site-packages\django\shortcuts.py", line 25, in render
    content = loader.render_to_string(template_name, context, request, using=using)
  File "C:\Users\User\Desktop\docs\.venv\Lib\site-packages\django\template\loader.py", line 61, in render_to_string
    template = get_template(template_name, using=using)
  File "C:\Users\User\Desktop\docs\.venv\Lib\site-packages\django\template\loader.py", line 19, in get_template
    raise TemplateDoesNotExist(template_name, chain=chain)
django.template.exceptions.TemplateDoesNotExist: templates/base.html
ERROR 2025-02-17 10:40:53,613 runserver HTTP GET /users/ 500 [0.23, 127.0.0.1:47756]
ERROR 2025-02-17 10:40:54,530 log Internal Server Error: /users/
Traceback (most recent call last):
  File "C:\Users\User\Desktop\docs\.venv\Lib\site-packages\asgiref\sync.py", line 518, in thread_handler
    raise exc_info[1]
  File "C:\Users\User\Desktop\docs\.venv\Lib\site-packages\django\core\handlers\exception.py", line 42, in inner
    response = await get_response(request)
               ^^^^^^^^^^^^^^^^^^^^^^^^^^^
  File "C:\Users\User\Desktop\docs\.venv\Lib\site-packages\asgiref\sync.py", line 518, in thread_handler
    raise exc_info[1]
  File "C:\Users\User\Desktop\docs\.venv\Lib\site-packages\django\core\handlers\base.py", line 253, in _get_response_async
    response = await wrapped_callback(
               ^^^^^^^^^^^^^^^^^^^^^^^
        request, *callback_args, **callback_kwargs
        ^^^^^^^^^^^^^^^^^^^^^^^^^^^^^^^^^^^^^^^^^^
    )
    ^
  File "C:\Users\User\Desktop\docs\.venv\Lib\site-packages\asgiref\sync.py", line 468, in __call__
    ret = await asyncio.shield(exec_coro)
          ^^^^^^^^^^^^^^^^^^^^^^^^^^^^^^^
  File "C:\Users\User\AppData\Local\Programs\Python\Python313\Lib\concurrent\futures\thread.py", line 59, in run
    result = self.fn(*self.args, **self.kwargs)
  File "C:\Users\User\Desktop\docs\.venv\Lib\site-packages\asgiref\sync.py", line 522, in thread_handler
    return func(*args, **kwargs)
  File "C:\Users\User\Desktop\docs\taskmanager\users\views.py", line 23, in index
    return render(request,'templates/base.html',context={'users':users, 'departments':departments, 'tasks':tasks})
  File "C:\Users\User\Desktop\docs\.venv\Lib\site-packages\django\shortcuts.py", line 25, in render
    content = loader.render_to_string(template_name, context, request, using=using)
  File "C:\Users\User\Desktop\docs\.venv\Lib\site-packages\django\template\loader.py", line 61, in render_to_string
    template = get_template(template_name, using=using)
  File "C:\Users\User\Desktop\docs\.venv\Lib\site-packages\django\template\loader.py", line 19, in get_template
    raise TemplateDoesNotExist(template_name, chain=chain)
django.template.exceptions.TemplateDoesNotExist: templates/base.html
ERROR 2025-02-17 10:40:54,533 runserver HTTP GET /users/ 500 [0.03, 127.0.0.1:47756]
ERROR 2025-02-17 10:40:55,076 log Internal Server Error: /users/
Traceback (most recent call last):
  File "C:\Users\User\Desktop\docs\.venv\Lib\site-packages\asgiref\sync.py", line 518, in thread_handler
    raise exc_info[1]
  File "C:\Users\User\Desktop\docs\.venv\Lib\site-packages\django\core\handlers\exception.py", line 42, in inner
    response = await get_response(request)
               ^^^^^^^^^^^^^^^^^^^^^^^^^^^
  File "C:\Users\User\Desktop\docs\.venv\Lib\site-packages\asgiref\sync.py", line 518, in thread_handler
    raise exc_info[1]
  File "C:\Users\User\Desktop\docs\.venv\Lib\site-packages\django\core\handlers\base.py", line 253, in _get_response_async
    response = await wrapped_callback(
               ^^^^^^^^^^^^^^^^^^^^^^^
        request, *callback_args, **callback_kwargs
        ^^^^^^^^^^^^^^^^^^^^^^^^^^^^^^^^^^^^^^^^^^
    )
    ^
  File "C:\Users\User\Desktop\docs\.venv\Lib\site-packages\asgiref\sync.py", line 468, in __call__
    ret = await asyncio.shield(exec_coro)
          ^^^^^^^^^^^^^^^^^^^^^^^^^^^^^^^
  File "C:\Users\User\AppData\Local\Programs\Python\Python313\Lib\concurrent\futures\thread.py", line 59, in run
    result = self.fn(*self.args, **self.kwargs)
  File "C:\Users\User\Desktop\docs\.venv\Lib\site-packages\asgiref\sync.py", line 522, in thread_handler
    return func(*args, **kwargs)
  File "C:\Users\User\Desktop\docs\taskmanager\users\views.py", line 23, in index
    return render(request,'templates/base.html',context={'users':users, 'departments':departments, 'tasks':tasks})
  File "C:\Users\User\Desktop\docs\.venv\Lib\site-packages\django\shortcuts.py", line 25, in render
    content = loader.render_to_string(template_name, context, request, using=using)
  File "C:\Users\User\Desktop\docs\.venv\Lib\site-packages\django\template\loader.py", line 61, in render_to_string
    template = get_template(template_name, using=using)
  File "C:\Users\User\Desktop\docs\.venv\Lib\site-packages\django\template\loader.py", line 19, in get_template
    raise TemplateDoesNotExist(template_name, chain=chain)
django.template.exceptions.TemplateDoesNotExist: templates/base.html
ERROR 2025-02-17 10:40:55,079 runserver HTTP GET /users/ 500 [0.03, 127.0.0.1:47756]
ERROR 2025-02-17 10:42:01,945 log Internal Server Error: /users/
Traceback (most recent call last):
  File "C:\Users\User\Desktop\docs\.venv\Lib\site-packages\asgiref\sync.py", line 518, in thread_handler
    raise exc_info[1]
  File "C:\Users\User\Desktop\docs\.venv\Lib\site-packages\django\core\handlers\exception.py", line 42, in inner
    response = await get_response(request)
               ^^^^^^^^^^^^^^^^^^^^^^^^^^^
  File "C:\Users\User\Desktop\docs\.venv\Lib\site-packages\asgiref\sync.py", line 518, in thread_handler
    raise exc_info[1]
  File "C:\Users\User\Desktop\docs\.venv\Lib\site-packages\django\core\handlers\base.py", line 253, in _get_response_async
    response = await wrapped_callback(
               ^^^^^^^^^^^^^^^^^^^^^^^
        request, *callback_args, **callback_kwargs
        ^^^^^^^^^^^^^^^^^^^^^^^^^^^^^^^^^^^^^^^^^^
    )
    ^
  File "C:\Users\User\Desktop\docs\.venv\Lib\site-packages\asgiref\sync.py", line 468, in __call__
    ret = await asyncio.shield(exec_coro)
          ^^^^^^^^^^^^^^^^^^^^^^^^^^^^^^^
  File "C:\Users\User\AppData\Local\Programs\Python\Python313\Lib\concurrent\futures\thread.py", line 59, in run
    result = self.fn(*self.args, **self.kwargs)
  File "C:\Users\User\Desktop\docs\.venv\Lib\site-packages\asgiref\sync.py", line 522, in thread_handler
    return func(*args, **kwargs)
  File "C:\Users\User\Desktop\docs\taskmanager\users\views.py", line 23, in index
    return render(request,'templates/base.html',context={'users':users, 'departments':departments, 'tasks':tasks})
  File "C:\Users\User\Desktop\docs\.venv\Lib\site-packages\django\shortcuts.py", line 25, in render
    content = loader.render_to_string(template_name, context, request, using=using)
  File "C:\Users\User\Desktop\docs\.venv\Lib\site-packages\django\template\loader.py", line 61, in render_to_string
    template = get_template(template_name, using=using)
  File "C:\Users\User\Desktop\docs\.venv\Lib\site-packages\django\template\loader.py", line 19, in get_template
    raise TemplateDoesNotExist(template_name, chain=chain)
django.template.exceptions.TemplateDoesNotExist: templates/base.html
ERROR 2025-02-17 10:42:01,948 runserver HTTP GET /users/ 500 [0.03, 127.0.0.1:47770]
ERROR 2025-02-17 10:42:14,184 log Internal Server Error: /users/
Traceback (most recent call last):
  File "C:\Users\User\Desktop\docs\.venv\Lib\site-packages\asgiref\sync.py", line 518, in thread_handler
    raise exc_info[1]
  File "C:\Users\User\Desktop\docs\.venv\Lib\site-packages\django\core\handlers\exception.py", line 42, in inner
    response = await get_response(request)
               ^^^^^^^^^^^^^^^^^^^^^^^^^^^
  File "C:\Users\User\Desktop\docs\.venv\Lib\site-packages\asgiref\sync.py", line 518, in thread_handler
    raise exc_info[1]
  File "C:\Users\User\Desktop\docs\.venv\Lib\site-packages\django\core\handlers\base.py", line 253, in _get_response_async
    response = await wrapped_callback(
               ^^^^^^^^^^^^^^^^^^^^^^^
        request, *callback_args, **callback_kwargs
        ^^^^^^^^^^^^^^^^^^^^^^^^^^^^^^^^^^^^^^^^^^
    )
    ^
  File "C:\Users\User\Desktop\docs\.venv\Lib\site-packages\asgiref\sync.py", line 468, in __call__
    ret = await asyncio.shield(exec_coro)
          ^^^^^^^^^^^^^^^^^^^^^^^^^^^^^^^
  File "C:\Users\User\AppData\Local\Programs\Python\Python313\Lib\concurrent\futures\thread.py", line 59, in run
    result = self.fn(*self.args, **self.kwargs)
  File "C:\Users\User\Desktop\docs\.venv\Lib\site-packages\asgiref\sync.py", line 522, in thread_handler
    return func(*args, **kwargs)
  File "C:\Users\User\Desktop\docs\taskmanager\users\views.py", line 23, in index
    return render(request,'taskmanager/templates/base.html',context={'users':users, 'departments':departments, 'tasks':tasks})
  File "C:\Users\User\Desktop\docs\.venv\Lib\site-packages\django\shortcuts.py", line 25, in render
    content = loader.render_to_string(template_name, context, request, using=using)
  File "C:\Users\User\Desktop\docs\.venv\Lib\site-packages\django\template\loader.py", line 61, in render_to_string
    template = get_template(template_name, using=using)
  File "C:\Users\User\Desktop\docs\.venv\Lib\site-packages\django\template\loader.py", line 19, in get_template
    raise TemplateDoesNotExist(template_name, chain=chain)
django.template.exceptions.TemplateDoesNotExist: taskmanager/templates/base.html
ERROR 2025-02-17 10:42:14,188 runserver HTTP GET /users/ 500 [0.13, 127.0.0.1:47778]
ERROR 2025-02-17 10:42:14,933 log Internal Server Error: /users/
Traceback (most recent call last):
  File "C:\Users\User\Desktop\docs\.venv\Lib\site-packages\asgiref\sync.py", line 518, in thread_handler
    raise exc_info[1]
  File "C:\Users\User\Desktop\docs\.venv\Lib\site-packages\django\core\handlers\exception.py", line 42, in inner
    response = await get_response(request)
               ^^^^^^^^^^^^^^^^^^^^^^^^^^^
  File "C:\Users\User\Desktop\docs\.venv\Lib\site-packages\asgiref\sync.py", line 518, in thread_handler
    raise exc_info[1]
  File "C:\Users\User\Desktop\docs\.venv\Lib\site-packages\django\core\handlers\base.py", line 253, in _get_response_async
    response = await wrapped_callback(
               ^^^^^^^^^^^^^^^^^^^^^^^
        request, *callback_args, **callback_kwargs
        ^^^^^^^^^^^^^^^^^^^^^^^^^^^^^^^^^^^^^^^^^^
    )
    ^
  File "C:\Users\User\Desktop\docs\.venv\Lib\site-packages\asgiref\sync.py", line 468, in __call__
    ret = await asyncio.shield(exec_coro)
          ^^^^^^^^^^^^^^^^^^^^^^^^^^^^^^^
  File "C:\Users\User\AppData\Local\Programs\Python\Python313\Lib\concurrent\futures\thread.py", line 59, in run
    result = self.fn(*self.args, **self.kwargs)
  File "C:\Users\User\Desktop\docs\.venv\Lib\site-packages\asgiref\sync.py", line 522, in thread_handler
    return func(*args, **kwargs)
  File "C:\Users\User\Desktop\docs\taskmanager\users\views.py", line 23, in index
    return render(request,'taskmanager/templates/base.html',context={'users':users, 'departments':departments, 'tasks':tasks})
  File "C:\Users\User\Desktop\docs\.venv\Lib\site-packages\django\shortcuts.py", line 25, in render
    content = loader.render_to_string(template_name, context, request, using=using)
  File "C:\Users\User\Desktop\docs\.venv\Lib\site-packages\django\template\loader.py", line 61, in render_to_string
    template = get_template(template_name, using=using)
  File "C:\Users\User\Desktop\docs\.venv\Lib\site-packages\django\template\loader.py", line 19, in get_template
    raise TemplateDoesNotExist(template_name, chain=chain)
django.template.exceptions.TemplateDoesNotExist: taskmanager/templates/base.html
ERROR 2025-02-17 10:42:14,937 runserver HTTP GET /users/ 500 [0.04, 127.0.0.1:47778]
WARNING 2025-02-17 10:47:13,058 log Not Found: /
WARNING 2025-02-17 10:47:13,059 runserver HTTP GET / 404 [0.02, 127.0.0.1:47809]
ERROR 2025-02-17 10:47:17,265 log Internal Server Error: /users/
Traceback (most recent call last):
  File "C:\Users\User\Desktop\docs\.venv\Lib\site-packages\asgiref\sync.py", line 518, in thread_handler
    raise exc_info[1]
  File "C:\Users\User\Desktop\docs\.venv\Lib\site-packages\django\core\handlers\exception.py", line 42, in inner
    response = await get_response(request)
               ^^^^^^^^^^^^^^^^^^^^^^^^^^^
  File "C:\Users\User\Desktop\docs\.venv\Lib\site-packages\asgiref\sync.py", line 518, in thread_handler
    raise exc_info[1]
  File "C:\Users\User\Desktop\docs\.venv\Lib\site-packages\django\core\handlers\base.py", line 253, in _get_response_async
    response = await wrapped_callback(
               ^^^^^^^^^^^^^^^^^^^^^^^
        request, *callback_args, **callback_kwargs
        ^^^^^^^^^^^^^^^^^^^^^^^^^^^^^^^^^^^^^^^^^^
    )
    ^
  File "C:\Users\User\Desktop\docs\.venv\Lib\site-packages\asgiref\sync.py", line 468, in __call__
    ret = await asyncio.shield(exec_coro)
          ^^^^^^^^^^^^^^^^^^^^^^^^^^^^^^^
  File "C:\Users\User\AppData\Local\Programs\Python\Python313\Lib\concurrent\futures\thread.py", line 59, in run
    result = self.fn(*self.args, **self.kwargs)
  File "C:\Users\User\Desktop\docs\.venv\Lib\site-packages\asgiref\sync.py", line 522, in thread_handler
    return func(*args, **kwargs)
  File "C:\Users\User\Desktop\docs\taskmanager\users\views.py", line 23, in index
    return render(request,'users/team_view.html',context={'users':users, 'departments':departments, 'tasks':tasks})
  File "C:\Users\User\Desktop\docs\.venv\Lib\site-packages\django\shortcuts.py", line 25, in render
    content = loader.render_to_string(template_name, context, request, using=using)
  File "C:\Users\User\Desktop\docs\.venv\Lib\site-packages\django\template\loader.py", line 61, in render_to_string
    template = get_template(template_name, using=using)
  File "C:\Users\User\Desktop\docs\.venv\Lib\site-packages\django\template\loader.py", line 19, in get_template
    raise TemplateDoesNotExist(template_name, chain=chain)
django.template.exceptions.TemplateDoesNotExist: users/team_view.html
ERROR 2025-02-17 10:47:17,270 runserver HTTP GET /users/ 500 [0.21, 127.0.0.1:47809]
ERROR 2025-02-17 10:47:17,904 log Internal Server Error: /users/
Traceback (most recent call last):
  File "C:\Users\User\Desktop\docs\.venv\Lib\site-packages\asgiref\sync.py", line 518, in thread_handler
    raise exc_info[1]
  File "C:\Users\User\Desktop\docs\.venv\Lib\site-packages\django\core\handlers\exception.py", line 42, in inner
    response = await get_response(request)
               ^^^^^^^^^^^^^^^^^^^^^^^^^^^
  File "C:\Users\User\Desktop\docs\.venv\Lib\site-packages\asgiref\sync.py", line 518, in thread_handler
    raise exc_info[1]
  File "C:\Users\User\Desktop\docs\.venv\Lib\site-packages\django\core\handlers\base.py", line 253, in _get_response_async
    response = await wrapped_callback(
               ^^^^^^^^^^^^^^^^^^^^^^^
        request, *callback_args, **callback_kwargs
        ^^^^^^^^^^^^^^^^^^^^^^^^^^^^^^^^^^^^^^^^^^
    )
    ^
  File "C:\Users\User\Desktop\docs\.venv\Lib\site-packages\asgiref\sync.py", line 468, in __call__
    ret = await asyncio.shield(exec_coro)
          ^^^^^^^^^^^^^^^^^^^^^^^^^^^^^^^
  File "C:\Users\User\AppData\Local\Programs\Python\Python313\Lib\concurrent\futures\thread.py", line 59, in run
    result = self.fn(*self.args, **self.kwargs)
  File "C:\Users\User\Desktop\docs\.venv\Lib\site-packages\asgiref\sync.py", line 522, in thread_handler
    return func(*args, **kwargs)
  File "C:\Users\User\Desktop\docs\taskmanager\users\views.py", line 23, in index
    return render(request,'users/team_view.html',context={'users':users, 'departments':departments, 'tasks':tasks})
  File "C:\Users\User\Desktop\docs\.venv\Lib\site-packages\django\shortcuts.py", line 25, in render
    content = loader.render_to_string(template_name, context, request, using=using)
  File "C:\Users\User\Desktop\docs\.venv\Lib\site-packages\django\template\loader.py", line 61, in render_to_string
    template = get_template(template_name, using=using)
  File "C:\Users\User\Desktop\docs\.venv\Lib\site-packages\django\template\loader.py", line 19, in get_template
    raise TemplateDoesNotExist(template_name, chain=chain)
django.template.exceptions.TemplateDoesNotExist: users/team_view.html
ERROR 2025-02-17 10:47:17,910 runserver HTTP GET /users/ 500 [0.04, 127.0.0.1:47809]
ERROR 2025-02-17 10:47:53,560 log Internal Server Error: /users/
Traceback (most recent call last):
  File "C:\Users\User\Desktop\docs\.venv\Lib\site-packages\asgiref\sync.py", line 518, in thread_handler
    raise exc_info[1]
  File "C:\Users\User\Desktop\docs\.venv\Lib\site-packages\django\core\handlers\exception.py", line 42, in inner
    response = await get_response(request)
               ^^^^^^^^^^^^^^^^^^^^^^^^^^^
  File "C:\Users\User\Desktop\docs\.venv\Lib\site-packages\asgiref\sync.py", line 518, in thread_handler
    raise exc_info[1]
  File "C:\Users\User\Desktop\docs\.venv\Lib\site-packages\django\core\handlers\base.py", line 253, in _get_response_async
    response = await wrapped_callback(
               ^^^^^^^^^^^^^^^^^^^^^^^
        request, *callback_args, **callback_kwargs
        ^^^^^^^^^^^^^^^^^^^^^^^^^^^^^^^^^^^^^^^^^^
    )
    ^
  File "C:\Users\User\Desktop\docs\.venv\Lib\site-packages\asgiref\sync.py", line 468, in __call__
    ret = await asyncio.shield(exec_coro)
          ^^^^^^^^^^^^^^^^^^^^^^^^^^^^^^^
  File "C:\Users\User\AppData\Local\Programs\Python\Python313\Lib\concurrent\futures\thread.py", line 59, in run
    result = self.fn(*self.args, **self.kwargs)
  File "C:\Users\User\Desktop\docs\.venv\Lib\site-packages\asgiref\sync.py", line 522, in thread_handler
    return func(*args, **kwargs)
  File "C:\Users\User\Desktop\docs\taskmanager\users\views.py", line 23, in index
    return render(request,'users/team.html',context={'users':users, 'departments':departments, 'tasks':tasks})
  File "C:\Users\User\Desktop\docs\.venv\Lib\site-packages\django\shortcuts.py", line 25, in render
    content = loader.render_to_string(template_name, context, request, using=using)
  File "C:\Users\User\Desktop\docs\.venv\Lib\site-packages\django\template\loader.py", line 61, in render_to_string
    template = get_template(template_name, using=using)
  File "C:\Users\User\Desktop\docs\.venv\Lib\site-packages\django\template\loader.py", line 19, in get_template
    raise TemplateDoesNotExist(template_name, chain=chain)
django.template.exceptions.TemplateDoesNotExist: users/team.html
ERROR 2025-02-17 10:47:53,564 runserver HTTP GET /users/ 500 [0.11, 127.0.0.1:47820]
ERROR 2025-02-17 10:48:02,503 log Internal Server Error: /users/
Traceback (most recent call last):
  File "C:\Users\User\Desktop\docs\.venv\Lib\site-packages\asgiref\sync.py", line 518, in thread_handler
    raise exc_info[1]
  File "C:\Users\User\Desktop\docs\.venv\Lib\site-packages\django\core\handlers\exception.py", line 42, in inner
    response = await get_response(request)
               ^^^^^^^^^^^^^^^^^^^^^^^^^^^
  File "C:\Users\User\Desktop\docs\.venv\Lib\site-packages\asgiref\sync.py", line 518, in thread_handler
    raise exc_info[1]
  File "C:\Users\User\Desktop\docs\.venv\Lib\site-packages\django\core\handlers\base.py", line 253, in _get_response_async
    response = await wrapped_callback(
               ^^^^^^^^^^^^^^^^^^^^^^^
        request, *callback_args, **callback_kwargs
        ^^^^^^^^^^^^^^^^^^^^^^^^^^^^^^^^^^^^^^^^^^
    )
    ^
  File "C:\Users\User\Desktop\docs\.venv\Lib\site-packages\asgiref\sync.py", line 468, in __call__
    ret = await asyncio.shield(exec_coro)
          ^^^^^^^^^^^^^^^^^^^^^^^^^^^^^^^
  File "C:\Users\User\AppData\Local\Programs\Python\Python313\Lib\concurrent\futures\thread.py", line 59, in run
    result = self.fn(*self.args, **self.kwargs)
  File "C:\Users\User\Desktop\docs\.venv\Lib\site-packages\asgiref\sync.py", line 522, in thread_handler
    return func(*args, **kwargs)
  File "C:\Users\User\Desktop\docs\taskmanager\users\views.py", line 23, in index
    return render(request,'team.html',context={'users':users, 'departments':departments, 'tasks':tasks})
  File "C:\Users\User\Desktop\docs\.venv\Lib\site-packages\django\shortcuts.py", line 25, in render
    content = loader.render_to_string(template_name, context, request, using=using)
  File "C:\Users\User\Desktop\docs\.venv\Lib\site-packages\django\template\loader.py", line 61, in render_to_string
    template = get_template(template_name, using=using)
  File "C:\Users\User\Desktop\docs\.venv\Lib\site-packages\django\template\loader.py", line 19, in get_template
    raise TemplateDoesNotExist(template_name, chain=chain)
django.template.exceptions.TemplateDoesNotExist: team.html
ERROR 2025-02-17 10:48:02,508 runserver HTTP GET /users/ 500 [0.13, 127.0.0.1:47828]
ERROR 2025-02-17 10:48:03,258 log Internal Server Error: /users/
Traceback (most recent call last):
  File "C:\Users\User\Desktop\docs\.venv\Lib\site-packages\asgiref\sync.py", line 518, in thread_handler
    raise exc_info[1]
  File "C:\Users\User\Desktop\docs\.venv\Lib\site-packages\django\core\handlers\exception.py", line 42, in inner
    response = await get_response(request)
               ^^^^^^^^^^^^^^^^^^^^^^^^^^^
  File "C:\Users\User\Desktop\docs\.venv\Lib\site-packages\asgiref\sync.py", line 518, in thread_handler
    raise exc_info[1]
  File "C:\Users\User\Desktop\docs\.venv\Lib\site-packages\django\core\handlers\base.py", line 253, in _get_response_async
    response = await wrapped_callback(
               ^^^^^^^^^^^^^^^^^^^^^^^
        request, *callback_args, **callback_kwargs
        ^^^^^^^^^^^^^^^^^^^^^^^^^^^^^^^^^^^^^^^^^^
    )
    ^
  File "C:\Users\User\Desktop\docs\.venv\Lib\site-packages\asgiref\sync.py", line 468, in __call__
    ret = await asyncio.shield(exec_coro)
          ^^^^^^^^^^^^^^^^^^^^^^^^^^^^^^^
  File "C:\Users\User\AppData\Local\Programs\Python\Python313\Lib\concurrent\futures\thread.py", line 59, in run
    result = self.fn(*self.args, **self.kwargs)
  File "C:\Users\User\Desktop\docs\.venv\Lib\site-packages\asgiref\sync.py", line 522, in thread_handler
    return func(*args, **kwargs)
  File "C:\Users\User\Desktop\docs\taskmanager\users\views.py", line 23, in index
    return render(request,'team.html',context={'users':users, 'departments':departments, 'tasks':tasks})
  File "C:\Users\User\Desktop\docs\.venv\Lib\site-packages\django\shortcuts.py", line 25, in render
    content = loader.render_to_string(template_name, context, request, using=using)
  File "C:\Users\User\Desktop\docs\.venv\Lib\site-packages\django\template\loader.py", line 61, in render_to_string
    template = get_template(template_name, using=using)
  File "C:\Users\User\Desktop\docs\.venv\Lib\site-packages\django\template\loader.py", line 19, in get_template
    raise TemplateDoesNotExist(template_name, chain=chain)
django.template.exceptions.TemplateDoesNotExist: team.html
ERROR 2025-02-17 10:48:03,262 runserver HTTP GET /users/ 500 [0.04, 127.0.0.1:47828]
ERROR 2025-02-17 10:48:38,678 log Internal Server Error: /users/
Traceback (most recent call last):
  File "C:\Users\User\Desktop\docs\.venv\Lib\site-packages\django\core\handlers\exception.py", line 55, in inner
    response = get_response(request)
  File "C:\Users\User\Desktop\docs\.venv\Lib\site-packages\django\core\handlers\base.py", line 197, in _get_response
    response = wrapped_callback(request, *callback_args, **callback_kwargs)
  File "C:\Users\User\Desktop\docs\taskmanager\users\views.py", line 23, in index
    return render(request,'team.html',context={'users':users, 'departments':departments, 'tasks':tasks})
  File "C:\Users\User\Desktop\docs\.venv\Lib\site-packages\django\shortcuts.py", line 25, in render
    content = loader.render_to_string(template_name, context, request, using=using)
  File "C:\Users\User\Desktop\docs\.venv\Lib\site-packages\django\template\loader.py", line 61, in render_to_string
    template = get_template(template_name, using=using)
  File "C:\Users\User\Desktop\docs\.venv\Lib\site-packages\django\template\loader.py", line 19, in get_template
    raise TemplateDoesNotExist(template_name, chain=chain)
django.template.exceptions.TemplateDoesNotExist: team.html
ERROR 2025-02-17 10:48:38,680 basehttp "GET /users/ HTTP/1.1" 500 85618
WARNING 2025-02-17 10:51:08,096 log Not Found: /
WARNING 2025-02-17 10:51:08,096 basehttp "GET / HTTP/1.1" 404 3064
ERROR 2025-02-17 10:51:14,226 log Internal Server Error: /tasks/
Traceback (most recent call last):
  File "C:\Users\User\Desktop\docs\.venv\Lib\site-packages\django\core\handlers\exception.py", line 55, in inner
    response = get_response(request)
  File "C:\Users\User\Desktop\docs\.venv\Lib\site-packages\django\core\handlers\base.py", line 197, in _get_response
    response = wrapped_callback(request, *callback_args, **callback_kwargs)
  File "C:\Users\User\Desktop\docs\taskmanager\tasks\views.py", line 17, in taskpage
    return render(request, 'tasks/task.html')
  File "C:\Users\User\Desktop\docs\.venv\Lib\site-packages\django\shortcuts.py", line 25, in render
    content = loader.render_to_string(template_name, context, request, using=using)
  File "C:\Users\User\Desktop\docs\.venv\Lib\site-packages\django\template\loader.py", line 61, in render_to_string
    template = get_template(template_name, using=using)
  File "C:\Users\User\Desktop\docs\.venv\Lib\site-packages\django\template\loader.py", line 19, in get_template
    raise TemplateDoesNotExist(template_name, chain=chain)
django.template.exceptions.TemplateDoesNotExist: tasks/task.html
ERROR 2025-02-17 10:51:14,228 basehttp "GET /tasks/ HTTP/1.1" 500 83498
ERROR 2025-02-17 10:53:10,023 log Internal Server Error: /users/
Traceback (most recent call last):
  File "C:\Users\User\Desktop\docs\.venv\Lib\site-packages\django\template\base.py", line 510, in parse
    compile_func = self.tags[command]
                   ~~~~~~~~~^^^^^^^^^
KeyError: 'endfir'

During handling of the above exception, another exception occurred:

Traceback (most recent call last):
  File "C:\Users\User\Desktop\docs\.venv\Lib\site-packages\django\core\handlers\exception.py", line 55, in inner
    response = get_response(request)
  File "C:\Users\User\Desktop\docs\.venv\Lib\site-packages\django\core\handlers\base.py", line 197, in _get_response
    response = wrapped_callback(request, *callback_args, **callback_kwargs)
  File "C:\Users\User\Desktop\docs\taskmanager\users\views.py", line 23, in index
    return render(request,'users/team.html',context={'users':users, 'departments':departments, 'tasks':tasks})
  File "C:\Users\User\Desktop\docs\.venv\Lib\site-packages\django\shortcuts.py", line 25, in render
    content = loader.render_to_string(template_name, context, request, using=using)
  File "C:\Users\User\Desktop\docs\.venv\Lib\site-packages\django\template\loader.py", line 61, in render_to_string
    template = get_template(template_name, using=using)
  File "C:\Users\User\Desktop\docs\.venv\Lib\site-packages\django\template\loader.py", line 15, in get_template
    return engine.get_template(template_name)
           ~~~~~~~~~~~~~~~~~~~^^^^^^^^^^^^^^^
  File "C:\Users\User\Desktop\docs\.venv\Lib\site-packages\django\template\backends\django.py", line 79, in get_template
    return Template(self.engine.get_template(template_name), self)
                    ~~~~~~~~~~~~~~~~~~~~~~~~^^^^^^^^^^^^^^^
  File "C:\Users\User\Desktop\docs\.venv\Lib\site-packages\django\template\engine.py", line 177, in get_template
    template, origin = self.find_template(template_name)
                       ~~~~~~~~~~~~~~~~~~^^^^^^^^^^^^^^^
  File "C:\Users\User\Desktop\docs\.venv\Lib\site-packages\django\template\engine.py", line 159, in find_template
    template = loader.get_template(name, skip=skip)
  File "C:\Users\User\Desktop\docs\.venv\Lib\site-packages\django\template\loaders\cached.py", line 57, in get_template
    template = super().get_template(template_name, skip)
  File "C:\Users\User\Desktop\docs\.venv\Lib\site-packages\django\template\loaders\base.py", line 28, in get_template
    return Template(
        contents,
    ...<2 lines>...
        self.engine,
    )
  File "C:\Users\User\Desktop\docs\.venv\Lib\site-packages\django\template\base.py", line 154, in __init__
    self.nodelist = self.compile_nodelist()
                    ~~~~~~~~~~~~~~~~~~~~~^^
  File "C:\Users\User\Desktop\docs\.venv\Lib\site-packages\django\template\base.py", line 196, in compile_nodelist
    nodelist = parser.parse()
  File "C:\Users\User\Desktop\docs\.venv\Lib\site-packages\django\template\base.py", line 518, in parse
    raise self.error(token, e)
  File "C:\Users\User\Desktop\docs\.venv\Lib\site-packages\django\template\base.py", line 516, in parse
    compiled_result = compile_func(self, token)
  File "C:\Users\User\Desktop\docs\.venv\Lib\site-packages\django\template\defaulttags.py", line 862, in do_for
    nodelist_loop = parser.parse(
        (
    ...<2 lines>...
        )
    )
  File "C:\Users\User\Desktop\docs\.venv\Lib\site-packages\django\template\base.py", line 512, in parse
    self.invalid_block_tag(token, command, parse_until)
    ~~~~~~~~~~~~~~~~~~~~~~^^^^^^^^^^^^^^^^^^^^^^^^^^^^^
  File "C:\Users\User\Desktop\docs\.venv\Lib\site-packages\django\template\base.py", line 563, in invalid_block_tag
    raise self.error(
    ...<8 lines>...
    )
django.template.exceptions.TemplateSyntaxError: Invalid block tag on line 14: 'endfir', expected 'empty' or 'endfor'. Did you forget to register or load this tag?
ERROR 2025-02-17 10:53:10,028 basehttp "GET /users/ HTTP/1.1" 500 154801
ERROR 2025-02-17 10:53:39,554 log Internal Server Error: /users/
Traceback (most recent call last):
  File "C:\Users\User\Desktop\docs\.venv\Lib\site-packages\django\template\base.py", line 510, in parse
    compile_func = self.tags[command]
                   ~~~~~~~~~^^^^^^^^^
KeyError: 'endblock'

During handling of the above exception, another exception occurred:

Traceback (most recent call last):
  File "C:\Users\User\Desktop\docs\.venv\Lib\site-packages\django\core\handlers\exception.py", line 55, in inner
    response = get_response(request)
  File "C:\Users\User\Desktop\docs\.venv\Lib\site-packages\django\core\handlers\base.py", line 197, in _get_response
    response = wrapped_callback(request, *callback_args, **callback_kwargs)
  File "C:\Users\User\Desktop\docs\taskmanager\users\views.py", line 23, in index
    return render(request,'users/team.html',context={'users':users, 'departments':departments, 'tasks':tasks})
  File "C:\Users\User\Desktop\docs\.venv\Lib\site-packages\django\shortcuts.py", line 25, in render
    content = loader.render_to_string(template_name, context, request, using=using)
  File "C:\Users\User\Desktop\docs\.venv\Lib\site-packages\django\template\loader.py", line 61, in render_to_string
    template = get_template(template_name, using=using)
  File "C:\Users\User\Desktop\docs\.venv\Lib\site-packages\django\template\loader.py", line 15, in get_template
    return engine.get_template(template_name)
           ~~~~~~~~~~~~~~~~~~~^^^^^^^^^^^^^^^
  File "C:\Users\User\Desktop\docs\.venv\Lib\site-packages\django\template\backends\django.py", line 79, in get_template
    return Template(self.engine.get_template(template_name), self)
                    ~~~~~~~~~~~~~~~~~~~~~~~~^^^^^^^^^^^^^^^
  File "C:\Users\User\Desktop\docs\.venv\Lib\site-packages\django\template\engine.py", line 177, in get_template
    template, origin = self.find_template(template_name)
                       ~~~~~~~~~~~~~~~~~~^^^^^^^^^^^^^^^
  File "C:\Users\User\Desktop\docs\.venv\Lib\site-packages\django\template\engine.py", line 159, in find_template
    template = loader.get_template(name, skip=skip)
  File "C:\Users\User\Desktop\docs\.venv\Lib\site-packages\django\template\loaders\cached.py", line 57, in get_template
    template = super().get_template(template_name, skip)
  File "C:\Users\User\Desktop\docs\.venv\Lib\site-packages\django\template\loaders\base.py", line 28, in get_template
    return Template(
        contents,
    ...<2 lines>...
        self.engine,
    )
  File "C:\Users\User\Desktop\docs\.venv\Lib\site-packages\django\template\base.py", line 154, in __init__
    self.nodelist = self.compile_nodelist()
                    ~~~~~~~~~~~~~~~~~~~~~^^
  File "C:\Users\User\Desktop\docs\.venv\Lib\site-packages\django\template\base.py", line 196, in compile_nodelist
    nodelist = parser.parse()
  File "C:\Users\User\Desktop\docs\.venv\Lib\site-packages\django\template\base.py", line 512, in parse
    self.invalid_block_tag(token, command, parse_until)
    ~~~~~~~~~~~~~~~~~~~~~~^^^^^^^^^^^^^^^^^^^^^^^^^^^^^
  File "C:\Users\User\Desktop\docs\.venv\Lib\site-packages\django\template\base.py", line 573, in invalid_block_tag
    raise self.error(
    ...<3 lines>...
    )
django.template.exceptions.TemplateSyntaxError: Invalid block tag on line 12: 'endblock'. Did you forget to register or load this tag?
ERROR 2025-02-17 10:53:39,557 basehttp "GET /users/ HTTP/1.1" 500 137240
ERROR 2025-02-17 10:55:08,274 log Internal Server Error: /tasks/
Traceback (most recent call last):
  File "C:\Users\User\Desktop\docs\.venv\Lib\site-packages\django\core\handlers\exception.py", line 55, in inner
    response = get_response(request)
  File "C:\Users\User\Desktop\docs\.venv\Lib\site-packages\django\core\handlers\base.py", line 197, in _get_response
    response = wrapped_callback(request, *callback_args, **callback_kwargs)
  File "C:\Users\User\Desktop\docs\taskmanager\tasks\views.py", line 17, in taskpage
    return render(request, 'tasks/task.html')
  File "C:\Users\User\Desktop\docs\.venv\Lib\site-packages\django\shortcuts.py", line 25, in render
    content = loader.render_to_string(template_name, context, request, using=using)
  File "C:\Users\User\Desktop\docs\.venv\Lib\site-packages\django\template\loader.py", line 61, in render_to_string
    template = get_template(template_name, using=using)
  File "C:\Users\User\Desktop\docs\.venv\Lib\site-packages\django\template\loader.py", line 19, in get_template
    raise TemplateDoesNotExist(template_name, chain=chain)
django.template.exceptions.TemplateDoesNotExist: tasks/task.html
ERROR 2025-02-17 10:55:08,275 basehttp "GET /tasks/ HTTP/1.1" 500 83994
ERROR 2025-02-17 10:55:38,754 log Internal Server Error: /tasks/
Traceback (most recent call last):
  File "C:\Users\User\Desktop\docs\.venv\Lib\site-packages\django\core\handlers\exception.py", line 55, in inner
    response = get_response(request)
  File "C:\Users\User\Desktop\docs\.venv\Lib\site-packages\django\core\handlers\base.py", line 197, in _get_response
    response = wrapped_callback(request, *callback_args, **callback_kwargs)
  File "C:\Users\User\Desktop\docs\taskmanager\tasks\views.py", line 17, in taskpage
    return render(request, 'tasks/task.html')
  File "C:\Users\User\Desktop\docs\.venv\Lib\site-packages\django\shortcuts.py", line 25, in render
    content = loader.render_to_string(template_name, context, request, using=using)
  File "C:\Users\User\Desktop\docs\.venv\Lib\site-packages\django\template\loader.py", line 61, in render_to_string
    template = get_template(template_name, using=using)
  File "C:\Users\User\Desktop\docs\.venv\Lib\site-packages\django\template\loader.py", line 19, in get_template
    raise TemplateDoesNotExist(template_name, chain=chain)
django.template.exceptions.TemplateDoesNotExist: tasks/task.html
ERROR 2025-02-17 10:55:38,755 basehttp "GET /tasks/ HTTP/1.1" 500 83994
WARNING 2025-02-17 10:59:40,348 log Not Found: /base
WARNING 2025-02-17 10:59:40,348 basehttp "GET /base HTTP/1.1" 404 3094
ERROR 2025-02-17 10:59:52,633 log Internal Server Error: /users/base/
Traceback (most recent call last):
  File "C:\Users\User\Desktop\docs\.venv\Lib\site-packages\django\core\handlers\exception.py", line 55, in inner
    response = get_response(request)
  File "C:\Users\User\Desktop\docs\.venv\Lib\site-packages\django\core\handlers\base.py", line 197, in _get_response
    response = wrapped_callback(request, *callback_args, **callback_kwargs)
  File "C:\Users\User\Desktop\docs\taskmanager\users\views.py", line 18, in basepage
    return render(request,'base.html')
  File "C:\Users\User\Desktop\docs\.venv\Lib\site-packages\django\shortcuts.py", line 25, in render
    content = loader.render_to_string(template_name, context, request, using=using)
  File "C:\Users\User\Desktop\docs\.venv\Lib\site-packages\django\template\loader.py", line 61, in render_to_string
    template = get_template(template_name, using=using)
  File "C:\Users\User\Desktop\docs\.venv\Lib\site-packages\django\template\loader.py", line 19, in get_template
    raise TemplateDoesNotExist(template_name, chain=chain)
django.template.exceptions.TemplateDoesNotExist: base.html
ERROR 2025-02-17 10:59:52,635 basehttp "GET /users/base/ HTTP/1.1" 500 85599
WARNING 2025-02-17 11:20:26,091 log Not Found: /
WARNING 2025-02-17 11:20:26,093 basehttp "GET / HTTP/1.1" 404 3064
WARNING 2025-02-17 11:51:39,537 log Not Found: /
WARNING 2025-02-17 11:51:39,539 basehttp "GET / HTTP/1.1" 404 3064
WARNING 2025-02-17 12:04:44,046 log Not Found: /
WARNING 2025-02-17 12:04:44,047 basehttp "GET / HTTP/1.1" 404 3064
WARNING 2025-02-17 12:12:19,724 log Not Found: /
WARNING 2025-02-17 12:12:19,725 basehttp "GET / HTTP/1.1" 404 3064
WARNING 2025-02-17 12:12:24,660 base Session data corrupted
WARNING 2025-02-17 12:12:24,725 base Session data corrupted
WARNING 2025-02-17 12:12:26,990 base Session data corrupted
WARNING 2025-02-17 12:58:20,847 log Not Found: /
WARNING 2025-02-17 12:58:20,848 basehttp "GET / HTTP/1.1" 404 3064
WARNING 2025-02-17 15:20:52,937 log Not Found: /
WARNING 2025-02-17 15:20:52,938 basehttp "GET / HTTP/1.1" 404 3064
ERROR 2025-02-17 16:02:04,014 log Internal Server Error: /admin/users/department/add/
Traceback (most recent call last):
  File "C:\Users\User\Desktop\docs\.venv\Lib\site-packages\django\core\handlers\exception.py", line 55, in inner
    response = get_response(request)
  File "C:\Users\User\Desktop\docs\.venv\Lib\site-packages\django\core\handlers\base.py", line 197, in _get_response
    response = wrapped_callback(request, *callback_args, **callback_kwargs)
  File "C:\Users\User\Desktop\docs\.venv\Lib\site-packages\django\contrib\admin\options.py", line 718, in wrapper
    return self.admin_site.admin_view(view)(*args, **kwargs)
           ~~~~~~~~~~~~~~~~~~~~~~~~~~~~~~~~^^^^^^^^^^^^^^^^^
  File "C:\Users\User\Desktop\docs\.venv\Lib\site-packages\django\utils\decorators.py", line 188, in _view_wrapper
    result = _process_exception(request, e)
  File "C:\Users\User\Desktop\docs\.venv\Lib\site-packages\django\utils\decorators.py", line 186, in _view_wrapper
    response = view_func(request, *args, **kwargs)
  File "C:\Users\User\Desktop\docs\.venv\Lib\site-packages\django\views\decorators\cache.py", line 80, in _view_wrapper
    response = view_func(request, *args, **kwargs)
  File "C:\Users\User\Desktop\docs\.venv\Lib\site-packages\django\contrib\admin\sites.py", line 241, in inner
    return view(request, *args, **kwargs)
  File "C:\Users\User\Desktop\docs\.venv\Lib\site-packages\django\contrib\admin\options.py", line 1961, in add_view
    return self.changeform_view(request, None, form_url, extra_context)
           ~~~~~~~~~~~~~~~~~~~~^^^^^^^^^^^^^^^^^^^^^^^^^^^^^^^^^^^^^^^^
  File "C:\Users\User\Desktop\docs\.venv\Lib\site-packages\django\utils\decorators.py", line 48, in _wrapper
    return bound_method(*args, **kwargs)
  File "C:\Users\User\Desktop\docs\.venv\Lib\site-packages\django\utils\decorators.py", line 188, in _view_wrapper
    result = _process_exception(request, e)
  File "C:\Users\User\Desktop\docs\.venv\Lib\site-packages\django\utils\decorators.py", line 186, in _view_wrapper
    response = view_func(request, *args, **kwargs)
  File "C:\Users\User\Desktop\docs\.venv\Lib\site-packages\django\contrib\admin\options.py", line 1820, in changeform_view
    return self._changeform_view(request, object_id, form_url, extra_context)
           ~~~~~~~~~~~~~~~~~~~~~^^^^^^^^^^^^^^^^^^^^^^^^^^^^^^^^^^^^^^^^^^^^^
  File "C:\Users\User\Desktop\docs\.venv\Lib\site-packages\django\contrib\admin\options.py", line 1871, in _changeform_view
    self.save_model(request, new_object, form, not add)
    ~~~~~~~~~~~~~~~^^^^^^^^^^^^^^^^^^^^^^^^^^^^^^^^^^^^
  File "C:\Users\User\Desktop\docs\.venv\Lib\site-packages\django\contrib\admin\options.py", line 1294, in save_model
    obj.save()
    ~~~~~~~~^^
  File "C:\Users\User\Desktop\docs\taskmanager\users\models.py", line 164, in save
    User.objects.filter(department=self, status=User.ACTIVE).update(
    ~~~~~~~~~~~~~~~~~~~^^^^^^^^^^^^^^^^^^^^^^^^^^^^^^^^^^^^^
  File "C:\Users\User\Desktop\docs\.venv\Lib\site-packages\django\db\models\manager.py", line 87, in manager_method
    return getattr(self.get_queryset(), name)(*args, **kwargs)
           ~~~~~~~~~~~~~~~~~~~~~~~~~~~~~~~~~~^^^^^^^^^^^^^^^^^
  File "C:\Users\User\Desktop\docs\.venv\Lib\site-packages\django\db\models\query.py", line 1476, in filter
    return self._filter_or_exclude(False, args, kwargs)
           ~~~~~~~~~~~~~~~~~~~~~~~^^^^^^^^^^^^^^^^^^^^^
  File "C:\Users\User\Desktop\docs\.venv\Lib\site-packages\django\db\models\query.py", line 1494, in _filter_or_exclude
    clone._filter_or_exclude_inplace(negate, args, kwargs)
    ~~~~~~~~~~~~~~~~~~~~~~~~~~~~~~~~^^^^^^^^^^^^^^^^^^^^^^
  File "C:\Users\User\Desktop\docs\.venv\Lib\site-packages\django\db\models\query.py", line 1501, in _filter_or_exclude_inplace
    self._query.add_q(Q(*args, **kwargs))
    ~~~~~~~~~~~~~~~~~^^^^^^^^^^^^^^^^^^^^
  File "C:\Users\User\Desktop\docs\.venv\Lib\site-packages\django\db\models\sql\query.py", line 1609, in add_q
    clause, _ = self._add_q(q_object, self.used_aliases)
                ~~~~~~~~~~~^^^^^^^^^^^^^^^^^^^^^^^^^^^^^
  File "C:\Users\User\Desktop\docs\.venv\Lib\site-packages\django\db\models\sql\query.py", line 1641, in _add_q
    child_clause, needed_inner = self.build_filter(
                                 ~~~~~~~~~~~~~~~~~^
        child,
        ^^^^^^
    ...<7 lines>...
        update_join_types=update_join_types,
        ^^^^^^^^^^^^^^^^^^^^^^^^^^^^^^^^^^^^
    )
    ^
  File "C:\Users\User\Desktop\docs\.venv\Lib\site-packages\django\db\models\sql\query.py", line 1555, in build_filter
    condition = self.build_lookup(lookups, col, value)
  File "C:\Users\User\Desktop\docs\.venv\Lib\site-packages\django\db\models\sql\query.py", line 1385, in build_lookup
    lookup = lookup_class(lhs, rhs)
  File "C:\Users\User\Desktop\docs\.venv\Lib\site-packages\django\db\models\lookups.py", line 30, in __init__
    self.rhs = self.get_prep_lookup()
               ~~~~~~~~~~~~~~~~~~~~^^
  File "C:\Users\User\Desktop\docs\.venv\Lib\site-packages\django\db\models\fields\related_lookups.py", line 147, in get_prep_lookup
    self.rhs = get_normalized_value(self.rhs, self.lhs)[0]
               ~~~~~~~~~~~~~~~~~~~~^^^^^^^^^^^^^^^^^^^^
  File "C:\Users\User\Desktop\docs\.venv\Lib\site-packages\django\db\models\fields\related_lookups.py", line 45, in get_normalized_value
    raise ValueError("Model instances passed to related filters must be saved.")
ValueError: Model instances passed to related filters must be saved.
ERROR 2025-02-17 16:02:04,023 basehttp "POST /admin/users/department/add/ HTTP/1.1" 500 185433
ERROR 2025-02-17 16:04:03,639 log Internal Server Error: /admin/users/department/add/
Traceback (most recent call last):
  File "C:\Users\User\Desktop\docs\.venv\Lib\site-packages\django\core\handlers\exception.py", line 55, in inner
    response = get_response(request)
  File "C:\Users\User\Desktop\docs\.venv\Lib\site-packages\django\core\handlers\base.py", line 197, in _get_response
    response = wrapped_callback(request, *callback_args, **callback_kwargs)
  File "C:\Users\User\Desktop\docs\.venv\Lib\site-packages\django\contrib\admin\options.py", line 718, in wrapper
    return self.admin_site.admin_view(view)(*args, **kwargs)
           ~~~~~~~~~~~~~~~~~~~~~~~~~~~~~~~~^^^^^^^^^^^^^^^^^
  File "C:\Users\User\Desktop\docs\.venv\Lib\site-packages\django\utils\decorators.py", line 188, in _view_wrapper
    result = _process_exception(request, e)
  File "C:\Users\User\Desktop\docs\.venv\Lib\site-packages\django\utils\decorators.py", line 186, in _view_wrapper
    response = view_func(request, *args, **kwargs)
  File "C:\Users\User\Desktop\docs\.venv\Lib\site-packages\django\views\decorators\cache.py", line 80, in _view_wrapper
    response = view_func(request, *args, **kwargs)
  File "C:\Users\User\Desktop\docs\.venv\Lib\site-packages\django\contrib\admin\sites.py", line 241, in inner
    return view(request, *args, **kwargs)
  File "C:\Users\User\Desktop\docs\.venv\Lib\site-packages\django\contrib\admin\options.py", line 1961, in add_view
    return self.changeform_view(request, None, form_url, extra_context)
           ~~~~~~~~~~~~~~~~~~~~^^^^^^^^^^^^^^^^^^^^^^^^^^^^^^^^^^^^^^^^
  File "C:\Users\User\Desktop\docs\.venv\Lib\site-packages\django\utils\decorators.py", line 48, in _wrapper
    return bound_method(*args, **kwargs)
  File "C:\Users\User\Desktop\docs\.venv\Lib\site-packages\django\utils\decorators.py", line 188, in _view_wrapper
    result = _process_exception(request, e)
  File "C:\Users\User\Desktop\docs\.venv\Lib\site-packages\django\utils\decorators.py", line 186, in _view_wrapper
    response = view_func(request, *args, **kwargs)
  File "C:\Users\User\Desktop\docs\.venv\Lib\site-packages\django\contrib\admin\options.py", line 1820, in changeform_view
    return self._changeform_view(request, object_id, form_url, extra_context)
           ~~~~~~~~~~~~~~~~~~~~~^^^^^^^^^^^^^^^^^^^^^^^^^^^^^^^^^^^^^^^^^^^^^
  File "C:\Users\User\Desktop\docs\.venv\Lib\site-packages\django\contrib\admin\options.py", line 1871, in _changeform_view
    self.save_model(request, new_object, form, not add)
    ~~~~~~~~~~~~~~~^^^^^^^^^^^^^^^^^^^^^^^^^^^^^^^^^^^^
  File "C:\Users\User\Desktop\docs\.venv\Lib\site-packages\django\contrib\admin\options.py", line 1294, in save_model
    obj.save()
    ~~~~~~~~^^
  File "C:\Users\User\Desktop\docs\taskmanager\users\models.py", line 164, in save
    User.objects.filter(department=self, status=User.ACTIVE).update(
    ~~~~~~~~~~~~~~~~~~~^^^^^^^^^^^^^^^^^^^^^^^^^^^^^^^^^^^^^
  File "C:\Users\User\Desktop\docs\.venv\Lib\site-packages\django\db\models\manager.py", line 87, in manager_method
    return getattr(self.get_queryset(), name)(*args, **kwargs)
           ~~~~~~~~~~~~~~~~~~~~~~~~~~~~~~~~~~^^^^^^^^^^^^^^^^^
  File "C:\Users\User\Desktop\docs\.venv\Lib\site-packages\django\db\models\query.py", line 1476, in filter
    return self._filter_or_exclude(False, args, kwargs)
           ~~~~~~~~~~~~~~~~~~~~~~~^^^^^^^^^^^^^^^^^^^^^
  File "C:\Users\User\Desktop\docs\.venv\Lib\site-packages\django\db\models\query.py", line 1494, in _filter_or_exclude
    clone._filter_or_exclude_inplace(negate, args, kwargs)
    ~~~~~~~~~~~~~~~~~~~~~~~~~~~~~~~~^^^^^^^^^^^^^^^^^^^^^^
  File "C:\Users\User\Desktop\docs\.venv\Lib\site-packages\django\db\models\query.py", line 1501, in _filter_or_exclude_inplace
    self._query.add_q(Q(*args, **kwargs))
    ~~~~~~~~~~~~~~~~~^^^^^^^^^^^^^^^^^^^^
  File "C:\Users\User\Desktop\docs\.venv\Lib\site-packages\django\db\models\sql\query.py", line 1609, in add_q
    clause, _ = self._add_q(q_object, self.used_aliases)
                ~~~~~~~~~~~^^^^^^^^^^^^^^^^^^^^^^^^^^^^^
  File "C:\Users\User\Desktop\docs\.venv\Lib\site-packages\django\db\models\sql\query.py", line 1641, in _add_q
    child_clause, needed_inner = self.build_filter(
                                 ~~~~~~~~~~~~~~~~~^
        child,
        ^^^^^^
    ...<7 lines>...
        update_join_types=update_join_types,
        ^^^^^^^^^^^^^^^^^^^^^^^^^^^^^^^^^^^^
    )
    ^
  File "C:\Users\User\Desktop\docs\.venv\Lib\site-packages\django\db\models\sql\query.py", line 1555, in build_filter
    condition = self.build_lookup(lookups, col, value)
  File "C:\Users\User\Desktop\docs\.venv\Lib\site-packages\django\db\models\sql\query.py", line 1385, in build_lookup
    lookup = lookup_class(lhs, rhs)
  File "C:\Users\User\Desktop\docs\.venv\Lib\site-packages\django\db\models\lookups.py", line 30, in __init__
    self.rhs = self.get_prep_lookup()
               ~~~~~~~~~~~~~~~~~~~~^^
  File "C:\Users\User\Desktop\docs\.venv\Lib\site-packages\django\db\models\fields\related_lookups.py", line 147, in get_prep_lookup
    self.rhs = get_normalized_value(self.rhs, self.lhs)[0]
               ~~~~~~~~~~~~~~~~~~~~^^^^^^^^^^^^^^^^^^^^
  File "C:\Users\User\Desktop\docs\.venv\Lib\site-packages\django\db\models\fields\related_lookups.py", line 45, in get_normalized_value
    raise ValueError("Model instances passed to related filters must be saved.")
ValueError: Model instances passed to related filters must be saved.
ERROR 2025-02-17 16:04:03,642 basehttp "POST /admin/users/department/add/ HTTP/1.1" 500 185433
